Workbook

Sheet Controle Pagamentos
B1: CONTROLE DE PAGAMENTO — FINANCIAMENTO IMOBILIÁRIO
B3: DADOS DO CONTRATO
B4: Cliente: | C4: HENRY MAGNO DE OLIVEIRA SILVA | I4: CPF: | J4: 074.927.647-90
B5: Imóvel: | C5: Lote 13, Quadra C — Res. Parque das Nogueiras | I5: Data Contrato: | J5: 44034
B6: Valor Total: | C6: 186334.81 | E6: Entrada: | F6: 100000 | H6: Saldo: | I6: 86334.81 | K6: Parcelas: | L6: 120 × dia 10
B8: IDENTIFICAÇÃO | F8: VALORES (R$) | I8: IGPM | K8: CORREÇÃO ANUAL | P8: ENCARGOS ATRASO
B9: Nº | C9: ANO | D9: MÊS | E9: DATA PGTO | F9: VLR A PAGAR | G9: VLR PAGO | H9: SALDO BASE | I9: NÚM. ÍNDICE | J9: VAR. MENSAL | K9: IGPM ACUM 12M | L9: BASE ATUAL. | M9: JUROS COMP. | N9: VALOR ATUAL. | O9: SALDO DEVEDOR | P9: MULTA 2% | Q9: JUROS MORA 0,033%/dia
B10: ENT. | C10: 2020 | D10: JUL | E10: 44034 | F10: 100000 | G10: 100000 | H10: 86334.81 | I10: ='Índices IGPM'!C5 -> 810.083 | L10: =H10 -> 86334.81 | N10: =H10 -> 86334.81 | O10: =H10 -> 86334.81
B11: 1 | C11: 2020 | D11: AGO | F11: =Reajustes!H4 -> 719.46 | H11: =O10-IF(G11="",0,G11) -> 86334.81 | I11: ='Índices IGPM'!C6 -> 832.313 | J11: ='Índices IGPM'!D6 -> 0.027441633 | L11: =H11 -> 86334.81 | N11: =H11 -> 86334.81 | O11: =H11 -> 86334.81 | P11: =IF(AND(E11<>"",DAY(E11)>10),F11*0.02,0) -> 0 | Q11: =IF(AND(E11<>"",DAY(E11)>10),F11*0.00033*(DAY(E11)-10),0) -> 0
B12: 2 | C12: 2020 | D12: SET | F12: =Reajustes!H4 -> 719.46 | H12: =O11-IF(G12="",0,G12) -> 86334.81 | I12: ='Índices IGPM'!C7 -> 868.442 | J12: ='Índices IGPM'!D7 -> 0.043407949 | L12: =H12 -> 86334.81 | N12: =H12 -> 86334.81 | O12: =H12 -> 86334.81 | P12: =IF(AND(E12<>"",DAY(E12)>10),F12*0.02,0) -> 0 | Q12: =IF(AND(E12<>"",DAY(E12)>10),F12*0.00033*(DAY(E12)-10),0) -> 0
B13: 3 | C13: 2020 | D13: OUT | F13: =Reajustes!H4 -> 719.46 | H13: =O12-IF(G13="",0,G13) -> 86334.81 | I13: ='Índices IGPM'!C8 -> 896.505 | J13: ='Índices IGPM'!D8 -> 0.03231419 | L13: =H13 -> 86334.81 | N13: =H13 -> 86334.81 | O13: =H13 -> 86334.81 | P13: =IF(AND(E13<>"",DAY(E13)>10),F13*0.02,0) -> 0 | Q13: =IF(AND(E13<>"",DAY(E13)>10),F13*0.00033*(DAY(E13)-10),0) -> 0
B14: 4 | C14: 2020 | D14: NOV | F14: =Reajustes!H4 -> 719.46 | H14: =O13-IF(G14="",0,G14) -> 86334.81 | I14: ='Índices IGPM'!C9 -> 925.887 | J14: ='Índices IGPM'!D9 -> 0.032773939 | L14: =H14 -> 86334.81 | N14: =H14 -> 86334.81 | O14: =H14 -> 86334.81 | P14: =IF(AND(E14<>"",DAY(E14)>10),F14*0.02,0) -> 0 | Q14: =IF(AND(E14<>"",DAY(E14)>10),F14*0.00033*(DAY(E14)-10),0) -> 0
B15: 5 | C15: 2020 | D15: DEZ | F15: =Reajustes!H4 -> 719.46 | H15: =O14-IF(G15="",0,G15) -> 86334.81 | I15: ='Índices IGPM'!C10 -> 934.758 | J15: ='Índices IGPM'!D10 -> 0.0095810828 | L15: =H15 -> 86334.81 | N15: =H15 -> 86334.81 | O15: =H15 -> 86334.81 | P15: =IF(AND(E15<>"",DAY(E15)>10),F15*0.02,0) -> 0 | Q15: =IF(AND(E15<>"",DAY(E15)>10),F15*0.00033*(DAY(E15)-10),0) -> 0
B16: 6 | C16: 2021 | D16: JAN | F16: =Reajustes!H4 -> 719.46 | H16: =O15-IF(G16="",0,G16) -> 86334.81 | I16: ='Índices IGPM'!C11 -> 958.844 | J16: ='Índices IGPM'!D11 -> 0.025767097 | L16: =H16 -> 86334.81 | N16: =H16 -> 86334.81 | O16: =H16 -> 86334.81 | P16: =IF(AND(E16<>"",DAY(E16)>10),F16*0.02,0) -> 0 | Q16: =IF(AND(E16<>"",DAY(E16)>10),F16*0.00033*(DAY(E16)-10),0) -> 0
B17: 7 | C17: 2021 | D17: FEV | F17: =Reajustes!H4 -> 719.46 | H17: =O16-IF(G17="",0,G17) -> 86334.81 | I17: ='Índices IGPM'!C12 -> 983.063 | J17: ='Índices IGPM'!D12 -> 0.02525854 | L17: =H17 -> 86334.81 | N17: =H17 -> 86334.81 | O17: =H17 -> 86334.81 | P17: =IF(AND(E17<>"",DAY(E17)>10),F17*0.02,0) -> 0 | Q17: =IF(AND(E17<>"",DAY(E17)>10),F17*0.00033*(DAY(E17)-10),0) -> 0
B18: 8 | C18: 2021 | D18: MAR | F18: =Reajustes!H4 -> 719.46 | H18: =O17-IF(G18="",0,G18) -> 86334.81 | I18: ='Índices IGPM'!C13 -> 1011.948 | J18: ='Índices IGPM'!D13 -> 0.029382654 | L18: =H18 -> 86334.81 | N18: =H18 -> 86334.81 | O18: =H18 -> 86334.81 | P18: =IF(AND(E18<>"",DAY(E18)>10),F18*0.02,0) -> 0 | Q18: =IF(AND(E18<>"",DAY(E18)>10),F18*0.00033*(DAY(E18)-10),0) -> 0
B19: 9 | C19: 2021 | D19: ABR | F19: =Reajustes!H4 -> 719.46 | H19: =O18-IF(G19="",0,G19) -> 86334.81 | I19: ='Índices IGPM'!C14 -> 1027.211 | J19: ='Índices IGPM'!D14 -> 0.015082791 | L19: =H19 -> 86334.81 | N19: =H19 -> 86334.81 | O19: =H19 -> 86334.81 | P19: =IF(AND(E19<>"",DAY(E19)>10),F19*0.02,0) -> 0 | Q19: =IF(AND(E19<>"",DAY(E19)>10),F19*0.00033*(DAY(E19)-10),0) -> 0
B20: 10 | C20: 2021 | D20: MAI | F20: =Reajustes!H4 -> 719.46 | H20: =O19-IF(G20="",0,G20) -> 86334.81 | I20: ='Índices IGPM'!C15 -> 1069.289 | J20: ='Índices IGPM'!D15 -> 0.040963346 | L20: =H20 -> 86334.81 | N20: =H20 -> 86334.81 | O20: =H20 -> 86334.81 | P20: =IF(AND(E20<>"",DAY(E20)>10),F20*0.02,0) -> 0 | Q20: =IF(AND(E20<>"",DAY(E20)>10),F20*0.00033*(DAY(E20)-10),0) -> 0
B21: 11 | C21: 2021 | D21: JUN | F21: =Reajustes!H4 -> 719.46 | H21: =O20-IF(G21="",0,G21) -> 86334.81 | I21: ='Índices IGPM'!C16 -> 1075.733 | J21: ='Índices IGPM'!D16 -> 0.0060264344 | L21: =H21 -> 86334.81 | N21: =H21 -> 86334.81 | O21: =H21 -> 86334.81 | P21: =IF(AND(E21<>"",DAY(E21)>10),F21*0.02,0) -> 0 | Q21: =IF(AND(E21<>"",DAY(E21)>10),F21*0.00033*(DAY(E21)-10),0) -> 0
B22: 12 | C22: 2021 | D22: JUL | F22: =Reajustes!H4 -> 719.46 | H22: =O21-IF(G22="",0,G22) -> 86334.81 | I22: ='Índices IGPM'!C17 -> 1084.095 | J22: ='Índices IGPM'!D17 -> 0.0077733043 | K22: =Reajustes!F4 -> 0.33825176 | L22: =IF(K22=0,H22,H22*(1+K22)) -> 115537.71 | M22: =Reajustes!E5 -> 0.074424168 | N22: =L22*(1+M22) -> 124136.51 | O22: =N22 -> 124136.51 | P22: =IF(AND(E22<>"",DAY(E22)>10),F22*0.02,0) -> 0 | Q22: =IF(AND(E22<>"",DAY(E22)>10),F22*0.00033*(DAY(E22)-10),0) -> 0
B23: 13 | C23: 2021 | D23: AGO | F23: =Reajustes!H5 -> 1034.4756 | H23: =O22-IF(G23="",0,G23) -> 124136.51 | I23: ='Índices IGPM'!C18 -> 1091.29 | J23: ='Índices IGPM'!D18 -> 0.0066368722 | L23: =H23 -> 124136.51 | N23: =H23 -> 124136.51 | O23: =H23 -> 124136.51 | P23: =IF(AND(E23<>"",DAY(E23)>10),F23*0.02,0) -> 0 | Q23: =IF(AND(E23<>"",DAY(E23)>10),F23*0.00033*(DAY(E23)-10),0) -> 0
B24: 14 | C24: 2021 | D24: SET | F24: =Reajustes!H5 -> 1034.4756 | H24: =O23-IF(G24="",0,G24) -> 124136.51 | I24: ='Índices IGPM'!C19 -> 1084.312 | J24: ='Índices IGPM'!D19 -> -0.0063942673 | L24: =H24 -> 124136.51 | N24: =H24 -> 124136.51 | O24: =H24 -> 124136.51 | P24: =IF(AND(E24<>"",DAY(E24)>10),F24*0.02,0) -> 0 | Q24: =IF(AND(E24<>"",DAY(E24)>10),F24*0.00033*(DAY(E24)-10),0) -> 0
B25: 15 | C25: 2021 | D25: OUT | F25: =Reajustes!H5 -> 1034.4756 | H25: =O24-IF(G25="",0,G25) -> 124136.51 | I25: ='Índices IGPM'!C20 -> 1091.283 | J25: ='Índices IGPM'!D20 -> 0.0064289614 | L25: =H25 -> 124136.51 | N25: =H25 -> 124136.51 | O25: =H25 -> 124136.51 | P25: =IF(AND(E25<>"",DAY(E25)>10),F25*0.02,0) -> 0 | Q25: =IF(AND(E25<>"",DAY(E25)>10),F25*0.00033*(DAY(E25)-10),0) -> 0
B26: 16 | C26: 2021 | D26: NOV | F26: =Reajustes!H5 -> 1034.4756 | H26: =O25-IF(G26="",0,G26) -> 124136.51 | I26: ='Índices IGPM'!C21 -> 1091.483 | J26: ='Índices IGPM'!D21 -> 0.00018327052 | L26: =H26 -> 124136.51 | N26: =H26 -> 124136.51 | O26: =H26 -> 124136.51 | P26: =IF(AND(E26<>"",DAY(E26)>10),F26*0.02,0) -> 0 | Q26: =IF(AND(E26<>"",DAY(E26)>10),F26*0.00033*(DAY(E26)-10),0) -> 0
B27: 17 | C27: 2021 | D27: DEZ | F27: =Reajustes!H5 -> 1034.4756 | H27: =O26-IF(G27="",0,G27) -> 124136.51 | I27: ='Índices IGPM'!C22 -> 1100.988 | J27: ='Índices IGPM'!D22 -> 0.0087083354 | L27: =H27 -> 124136.51 | N27: =H27 -> 124136.51 | O27: =H27 -> 124136.51 | P27: =IF(AND(E27<>"",DAY(E27)>10),F27*0.02,0) -> 0 | Q27: =IF(AND(E27<>"",DAY(E27)>10),F27*0.00033*(DAY(E27)-10),0) -> 0
B28: 18 | C28: 2022 | D28: JAN | F28: =Reajustes!H5 -> 1034.4756 | H28: =O27-IF(G28="",0,G28) -> 124136.51 | I28: ='Índices IGPM'!C23 -> 1120.999 | J28: ='Índices IGPM'!D23 -> 0.018175493 | L28: =H28 -> 124136.51 | N28: =H28 -> 124136.51 | O28: =H28 -> 124136.51 | P28: =IF(AND(E28<>"",DAY(E28)>10),F28*0.02,0) -> 0 | Q28: =IF(AND(E28<>"",DAY(E28)>10),F28*0.00033*(DAY(E28)-10),0) -> 0
B29: 19 | C29: 2022 | D29: FEV | F29: =Reajustes!H5 -> 1034.4756 | H29: =O28-IF(G29="",0,G29) -> 124136.51 | I29: ='Índices IGPM'!C24 -> 1141.546 | J29: ='Índices IGPM'!D24 -> 0.018329187 | L29: =H29 -> 124136.51 | N29: =H29 -> 124136.51 | O29: =H29 -> 124136.51 | P29: =IF(AND(E29<>"",DAY(E29)>10),F29*0.02,0) -> 0 | Q29: =IF(AND(E29<>"",DAY(E29)>10),F29*0.00033*(DAY(E29)-10),0) -> 0
B30: 20 | C30: 2022 | D30: MAR | F30: =Reajustes!H5 -> 1034.4756 | H30: =O29-IF(G30="",0,G30) -> 124136.51 | I30: ='Índices IGPM'!C25 -> 1161.418 | J30: ='Índices IGPM'!D25 -> 0.017407971 | L30: =H30 -> 124136.51 | N30: =H30 -> 124136.51 | O30: =H30 -> 124136.51 | P30: =IF(AND(E30<>"",DAY(E30)>10),F30*0.02,0) -> 0 | Q30: =IF(AND(E30<>"",DAY(E30)>10),F30*0.00033*(DAY(E30)-10),0) -> 0
B31: 21 | C31: 2022 | D31: ABR | F31: =Reajustes!H5 -> 1034.4756 | H31: =O30-IF(G31="",0,G31) -> 124136.51 | I31: ='Índices IGPM'!C26 -> 1177.809 | J31: ='Índices IGPM'!D26 -> 0.014112921 | L31: =H31 -> 124136.51 | N31: =H31 -> 124136.51 | O31: =H31 -> 124136.51 | P31: =IF(AND(E31<>"",DAY(E31)>10),F31*0.02,0) -> 0 | Q31: =IF(AND(E31<>"",DAY(E31)>10),F31*0.00033*(DAY(E31)-10),0) -> 0
B32: 22 | C32: 2022 | D32: MAI | F32: =Reajustes!H5 -> 1034.4756 | H32: =O31-IF(G32="",0,G32) -> 124136.51 | I32: ='Índices IGPM'!C27 -> 1183.953 | J32: ='Índices IGPM'!D27 -> 0.0052164655 | L32: =H32 -> 124136.51 | N32: =H32 -> 124136.51 | O32: =H32 -> 124136.51 | P32: =IF(AND(E32<>"",DAY(E32)>10),F32*0.02,0) -> 0 | Q32: =IF(AND(E32<>"",DAY(E32)>10),F32*0.00033*(DAY(E32)-10),0) -> 0
B33: 23 | C33: 2022 | D33: JUN | F33: =Reajustes!H5 -> 1034.4756 | H33: =O32-IF(G33="",0,G33) -> 124136.51 | I33: ='Índices IGPM'!C28 -> 1190.882 | J33: ='Índices IGPM'!D28 -> 0.0058524283 | L33: =H33 -> 124136.51 | N33: =H33 -> 124136.51 | O33: =H33 -> 124136.51 | P33: =IF(AND(E33<>"",DAY(E33)>10),F33*0.02,0) -> 0 | Q33: =IF(AND(E33<>"",DAY(E33)>10),F33*0.00033*(DAY(E33)-10),0) -> 0
B34: 24 | C34: 2022 | D34: JUL | F34: =Reajustes!H5 -> 1034.4756 | H34: =O33-IF(G34="",0,G34) -> 124136.51 | I34: ='Índices IGPM'!C29 -> 1193.337 | J34: ='Índices IGPM'!D29 -> 0.0020614973 | K34: =Reajustes!F5 -> 0.10076792 | L34: =IF(K34=0,H34,H34*(1+K34)) -> 136645.49 | M34: =Reajustes!E6 -> 0.08084981 | N34: =L34*(1+M34) -> 147693.25 | O34: =N34 -> 147693.25 | P34: =IF(AND(E34<>"",DAY(E34)>10),F34*0.02,0) -> 0 | Q34: =IF(AND(E34<>"",DAY(E34)>10),F34*0.00033*(DAY(E34)-10),0) -> 0
B35: 25 | C35: 2022 | D35: AGO | F35: =Reajustes!H6 -> 1230.7826 | H35: =O34-IF(G35="",0,G35) -> 147693.25 | I35: ='Índices IGPM'!C30 -> 1185.004 | J35: ='Índices IGPM'!D30 -> -0.0069829394 | L35: =H35 -> 147693.25 | N35: =H35 -> 147693.25 | O35: =H35 -> 147693.25 | P35: =IF(AND(E35<>"",DAY(E35)>10),F35*0.02,0) -> 0 | Q35: =IF(AND(E35<>"",DAY(E35)>10),F35*0.00033*(DAY(E35)-10),0) -> 0
B36: 26 | C36: 2022 | D36: SET | F36: =Reajustes!H6 -> 1230.7826 | H36: =O35-IF(G36="",0,G36) -> 147693.25 | I36: ='Índices IGPM'!C31 -> 1173.793 | J36: ='Índices IGPM'!D31 -> -0.0094607276 | L36: =H36 -> 147693.25 | N36: =H36 -> 147693.25 | O36: =H36 -> 147693.25 | P36: =IF(AND(E36<>"",DAY(E36)>10),F36*0.02,0) -> 0 | Q36: =IF(AND(E36<>"",DAY(E36)>10),F36*0.00033*(DAY(E36)-10),0) -> 0
B37: 27 | C37: 2022 | D37: OUT | F37: =Reajustes!H6 -> 1230.7826 | H37: =O36-IF(G37="",0,G37) -> 147693.25 | I37: ='Índices IGPM'!C32 -> 1162.391 | J37: ='Índices IGPM'!D32 -> -0.0097138081 | L37: =H37 -> 147693.25 | N37: =H37 -> 147693.25 | O37: =H37 -> 147693.25 | P37: =IF(AND(E37<>"",DAY(E37)>10),F37*0.02,0) -> 0 | Q37: =IF(AND(E37<>"",DAY(E37)>10),F37*0.00033*(DAY(E37)-10),0) -> 0
B38: 28 | C38: 2022 | D38: NOV | F38: =Reajustes!H6 -> 1230.7826 | H38: =O37-IF(G38="",0,G38) -> 147693.25 | I38: ='Índices IGPM'!C33 -> 1155.829 | J38: ='Índices IGPM'!D33 -> -0.0056452605 | L38: =H38 -> 147693.25 | N38: =H38 -> 147693.25 | O38: =H38 -> 147693.25 | P38: =IF(AND(E38<>"",DAY(E38)>10),F38*0.02,0) -> 0 | Q38: =IF(AND(E38<>"",DAY(E38)>10),F38*0.00033*(DAY(E38)-10),0) -> 0
B39: 29 | C39: 2022 | D39: DEZ | F39: =Reajustes!H6 -> 1230.7826 | H39: =O38-IF(G39="",0,G39) -> 147693.25 | I39: ='Índices IGPM'!C34 -> 1161.006 | J39: ='Índices IGPM'!D34 -> 0.0044790363 | L39: =H39 -> 147693.25 | N39: =H39 -> 147693.25 | O39: =H39 -> 147693.25 | P39: =IF(AND(E39<>"",DAY(E39)>10),F39*0.02,0) -> 0 | Q39: =IF(AND(E39<>"",DAY(E39)>10),F39*0.00033*(DAY(E39)-10),0) -> 0
B40: 30 | C40: 2023 | D40: JAN | F40: =Reajustes!H6 -> 1230.7826 | H40: =O39-IF(G40="",0,G40) -> 147693.25 | I40: ='Índices IGPM'!C35 -> 1163.465 | J40: ='Índices IGPM'!D35 -> 0.0021179908 | L40: =H40 -> 147693.25 | N40: =H40 -> 147693.25 | O40: =H40 -> 147693.25 | P40: =IF(AND(E40<>"",DAY(E40)>10),F40*0.02,0) -> 0 | Q40: =IF(AND(E40<>"",DAY(E40)>10),F40*0.00033*(DAY(E40)-10),0) -> 0
B41: 31 | C41: 2023 | D41: FEV | F41: =Reajustes!H6 -> 1230.7826 | H41: =O40-IF(G41="",0,G41) -> 147693.25 | I41: ='Índices IGPM'!C36 -> 1162.761 | J41: ='Índices IGPM'!D36 -> -0.00060508911 | L41: =H41 -> 147693.25 | N41: =H41 -> 147693.25 | O41: =H41 -> 147693.25 | P41: =IF(AND(E41<>"",DAY(E41)>10),F41*0.02,0) -> 0 | Q41: =IF(AND(E41<>"",DAY(E41)>10),F41*0.00033*(DAY(E41)-10),0) -> 0
B42: 32 | C42: 2023 | D42: MAR | F42: =Reajustes!H6 -> 1230.7826 | H42: =O41-IF(G42="",0,G42) -> 147693.25 | I42: ='Índices IGPM'!C37 -> 1163.359 | J42: ='Índices IGPM'!D37 -> 0.00051429314 | L42: =H42 -> 147693.25 | N42: =H42 -> 147693.25 | O42: =H42 -> 147693.25 | P42: =IF(AND(E42<>"",DAY(E42)>10),F42*0.02,0) -> 0 | Q42: =IF(AND(E42<>"",DAY(E42)>10),F42*0.00033*(DAY(E42)-10),0) -> 0
...

Sheet Índices IGPM
A1: SÉRIE HISTÓRICA IGPM - FGV/IBRE
A2: Fonte: FGV/IBRE | Atualizado até FEV/2026 | Início: JUN/2020 (mês do contrato)
A3: ANO | B3: MÊS | C3: NÚM. ÍNDICE | D3: VAR. MENSAL | E3: VAR. ACUM. DESDE JUN/20
A4: 2020 | B4: JUN | C4: 792.429 | E4: 0
A5: 2020 | B5: JUL | C5: 810.083 | D5: =(C5-C4)/C4 -> 0.022278337 | E5: =C5/C$4-1 -> 0.022278337
A6: 2020 | B6: AGO | C6: 832.313 | D6: =(C6-C5)/C5 -> 0.027441633 | E6: =C6/C$4-1 -> 0.050331323
A7: 2020 | B7: SET | C7: 868.442 | D7: =(C7-C6)/C6 -> 0.043407949 | E7: =C7/C$4-1 -> 0.095924051
A8: 2020 | B8: OUT | C8: 896.505 | D8: =(C8-C7)/C7 -> 0.03231419 | E8: =C8/C$4-1 -> 0.13133795
A9: 2020 | B9: NOV | C9: 925.887 | D9: =(C9-C8)/C8 -> 0.032773939 | E9: =C9/C$4-1 -> 0.16841635
A10: 2020 | B10: DEZ | C10: 934.758 | D10: =(C10-C9)/C9 -> 0.0095810828 | E10: =C10/C$4-1 -> 0.17961104
A11: 2021 | B11: JAN | C11: 958.844 | D11: =(C11-C10)/C10 -> 0.025767097 | E11: =C11/C$4-1 -> 0.2100062
A12: 2021 | B12: FEV | C12: 983.063 | D12: =(C12-C11)/C11 -> 0.02525854 | E12: =C12/C$4-1 -> 0.24056919
A13: 2021 | B13: MAR | C13: 1011.948 | D13: =(C13-C12)/C12 -> 0.029382654 | E13: =C13/C$4-1 -> 0.2770204
A14: 2021 | B14: ABR | C14: 1027.211 | D14: =(C14-C13)/C13 -> 0.015082791 | E14: =C14/C$4-1 -> 0.29628143
A15: 2021 | B15: MAI | C15: 1069.289 | D15: =(C15-C14)/C14 -> 0.040963346 | E15: =C15/C$4-1 -> 0.34938146
A16: 2021 | B16: JUN | C16: 1075.733 | D16: =(C16-C15)/C15 -> 0.0060264344 | E16: =C16/C$4-1 -> 0.35751342
... A72: 2026 | B72: FEV | C72: 1181.306 | D72: =(C72-C71)/C71 -> -0.0073000429 | E72: =C72/C$4-1 -> 0.4907405

Sheet Reajustes
A1: PARÂMETROS DE REAJUSTE ANUAL
A2: Cláusula 2.2 - Correção: IGPM acumulado 12 meses + Juros compostos mensais
A3: ANO CONTRATUAL | B3: PARCELAS | C3: PERÍODO | D3: JUROS a.m. | E3: JUROS COMP. 12 MESES | F3: IGPM ACUM 12 MESES | G3: FATOR CORREÇÃO | H3: PARCELA MENSAL (R$)
A4: 1º ANO | B4: 1 - 12 | C4: AGO/20 a JUL/21 | D4: 0 | E4: 0 | F4: ='Índices IGPM'!C17/'Índices IGPM'!C5-1 -> 0.33825176 | G4: 1 | H4: 719.46
A5: 2º ANO | B5: 13 - 24 | C5: AGO/21 a JUL/22 | D5: 0.006 | E5: =(1+D5)^12-1 -> 0.074424168 | F5: ='Índices IGPM'!C29/'Índices IGPM'!C17-1 -> 0.10076792 | G5: =IF(F4=0,1,(1+F4)*(1+E5)) -> 1.43785 | H5: =H4*G5 -> 1034.4756
A6: 3º ANO | B6: 25 - 36 | C6: AGO/22 a JUL/23 | D6: 0.0065 | E6: =(1+D6)^12-1 -> 0.08084981 | F6: ='Índices IGPM'!C41/'Índices IGPM'!C29-1 -> -0.077206187 | G6: =IF(F5=0,1,(1+F5)*(1+E6)) -> 1.1897648 | H6: =H5*G6 -> 1230.7826
A7: 4º ANO | B7: 37 - 48 | C7: AGO/23 a JUL/24 | D7: 0.007 | E7: =(1+D7)^12-1 -> 0.087310662 | F7: ='Índices IGPM'!C53/'Índices IGPM'!C41-1 -> 0.038239055 | G7: =IF(F6=0,1,(1+F6)*(1+E7)) -> 1.0033636 | H7: =H6*G7 -> 1234.9224
A8: 5º ANO | B8: 49 - 60 | C8: AGO/24 a JUL/25 | D8: 0.0075 | E8: =(1+D8)^12-1 -> 0.093806898 | F8: ='Índices IGPM'!C65/'Índices IGPM'!C53-1 -> 0.029579826 | G8: =IF(F7=0,1,(1+F7)*(1+E8)) -> 1.135633 | H8: =H7*G8 -> 1402.4187
A9: 6º ANO | B9: 61 - 72 | C9: AGO/25 a JUL/26 | D9: 0.008 | E9: =(1+D9)^12-1 -> 0.10033869 | F9: 0 | G9: =IF(F8=0,1,(1+F8)*(1+E9)) -> 1.1328865 | H9: =H8*G9 -> 1588.7813
A10: 7º ANO | B10: 73 - 84 | C10: AGO/26 a JUL/27 | D10: 0.0085 | E10: =(1+D10)^12-1 -> 0.10690623 | F10: 0 | G10: =IF(F9=0,1,(1+F9)*(1+E10)) -> 1 | H10: =H9*G10 -> 1588.7813
A11: 8º ANO | B11: 85 - 96 | C11: AGO/27 a JUL/28 | D11: 0.0085 | E11: =(1+D11)^12-1 -> 0.10690623 | F11: 0 | G11: =IF(F10=0,1,(1+F10)*(1+E11)) -> 1 | H11: =H10*G11 -> 1588.7813
A12: 9º ANO | B12: 97 - 108 | C12: AGO/28 a JUL/29 | D12: 0.0085 | E12: =(1+D12)^12-1 -> 0.10690623 | F12: 0 | G12: =IF(F11=0,1,(1+F11)*(1+E12)) -> 1 | H12: =H11*G12 -> 1588.7813
A13: 10º ANO | B13: 109 - 120 | C13: AGO/29 a JUL/30 | D13: 0.0085 | E13: =(1+D13)^12-1 -> 0.10690623 | F13: 0 | G13: =IF(F12=0,1,(1+F12)*(1+E13)) -> 1 | H13: =H12*G13 -> 1588.7813
A15: FÓRMULA: Parcela(N) = Parcela(N-1) × Fator Correção
A16: FATOR: (1 + IGPM acum 12m do ano anterior) × (1 + Juros compostos 12m do ano corrente)
A17: IGPM: calculado JUL/ano anterior ÷ JUL/ano retrasado - conforme cláusula 2.2
