Workbook

Sheet Parcelas Mensais
B1: CONTROLE — PARCELAS MENSAIS (Cláusula 2.2.1)
B3: DADOS DO CONTRATO
B4: Compradora: | C4: UANDA SILVA CARVALHO | J4: CPF: | K4: 066.128.216-39
B5: Imóvel: | C5: Lote 16, Quadra D — Res. Parque das Nogueiras | J5: Data Contrato: | K5: 44279
B6: Valor Total: | C6: 235695.82 | E6: Entrada: | F6: 23569.58 | H6: Saldo Mensal: | I6: 162126.24 | K6: Parcelas: | L6: 120 × dia 10 | N6: Índice: | O6: IPCA + 0,85% a.m.
B8: IDENTIFICAÇÃO | F8: VALORES (R$) | I8: IPCA | K8: CORREÇÃO ANUAL | P8: ENCARGOS ATRASO | R8: CLÁUS. 2.2.2
B9: Nº | C9: ANO | D9: MÊS | E9: DATA PGTO | F9: VLR A PAGAR | G9: VLR PAGO | H9: SALDO BASE | I9: NÚM. ÍNDICE | J9: VAR. MENSAL | K9: IPCA ACUM 12M | L9: BASE ATUAL. | M9: JUROS COMP. | N9: VALOR ATUAL. | O9: SALDO DEVEDOR | P9: MULTA 2% (R$) | Q9: JUROS MORA 0,033%/dia | R9: SALDO REM. ANUAL (R$) | S9: ANUAL PAGO (R$)
B10: ENT. | C10: 2021 | D10: MAR | E10: 44279 | F10: 23569.58 | G10: 23569.58 | H10: 162126.24 | I10: ='Índices IPCA'!C4 -> 5674.72 | L10: =H10 -> 162126.24 | N10: =H10 -> 162126.24 | O10: =H10 -> 162126.24
B11: 1 | C11: 2021 | D11: ABR | E11: 44298 | F11: =Reajustes!H4 -> 1351.05 | G11: 1392.72 | H11: =O10-IF(G11="",0,G11) -> 160733.52 | I11: ='Índices IPCA'!C5 -> 5692.31 | J11: ='Índices IPCA'!D5 -> 0.0030997124 | L11: =H11 -> 160733.52 | N11: =H11 -> 160733.52 | O11: =H11 -> 160733.52 | P11: =IF(AND(E11<>"",E11>Vencimentos!D3),F11*0.02,0) -> 0 | Q11: =IF(AND(E11<>"",E11>Vencimentos!D3),F11*0.00033*(E11-Vencimentos!D3),0) -> 0
B12: 2 | C12: 2021 | D12: MAI | E12: 44323 | F12: =Reajustes!H4 -> 1351.05 | G12: 1392.72 | H12: =O11-IF(G12="",0,G12) -> 159340.8 | I12: ='Índices IPCA'!C6 -> 5739.56 | J12: ='Índices IPCA'!D6 -> 0.0083006723 | L12: =H12 -> 159340.8 | N12: =H12 -> 159340.8 | O12: =H12 -> 159340.8 | P12: =IF(AND(E12<>"",E12>Vencimentos!D4),F12*0.02,0) -> 0 | Q12: =IF(AND(E12<>"",E12>Vencimentos!D4),F12*0.00033*(E12-Vencimentos!D4),0) -> 0
B13: 3 | C13: 2021 | D13: JUN | E13: 44357 | F13: =Reajustes!H4 -> 1351.05 | G13: 1392.72 | H13: =O12-IF(G13="",0,G13) -> 157948.08 | I13: ='Índices IPCA'!C7 -> 5769.98 | J13: ='Índices IPCA'!D7 -> 0.0053000578 | L13: =H13 -> 157948.08 | N13: =H13 -> 157948.08 | O13: =H13 -> 157948.08 | P13: =IF(AND(E13<>"",E13>Vencimentos!D5),F13*0.02,0) -> 0 | Q13: =IF(AND(E13<>"",E13>Vencimentos!D5),F13*0.00033*(E13-Vencimentos!D5),0) -> 0
B14: 4 | C14: 2021 | D14: JUL | E14: 44386 | F14: =Reajustes!H4 -> 1351.05 | G14: 1392.72 | H14: =O13-IF(G14="",0,G14) -> 156555.36 | I14: ='Índices IPCA'!C8 -> 5825.37 | J14: ='Índices IPCA'!D8 -> 0.0095996867 | L14: =H14 -> 156555.36 | N14: =H14 -> 156555.36 | O14: =H14 -> 156555.36 | P14: =IF(AND(E14<>"",E14>Vencimentos!D6),F14*0.02,0) -> 0 | Q14: =IF(AND(E14<>"",E14>Vencimentos!D6),F14*0.00033*(E14-Vencimentos!D6),0) -> 0
B15: 5 | C15: 2021 | D15: AGO | E15: 44413 | F15: =Reajustes!H4 -> 1351.05 | G15: 1392.72 | H15: =O14-IF(G15="",0,G15) -> 155162.64 | I15: ='Índices IPCA'!C9 -> 5876.05 | J15: ='Índices IPCA'!D9 -> 0.0086998766 | L15: =H15 -> 155162.64 | N15: =H15 -> 155162.64 | O15: =H15 -> 155162.64 | P15: =IF(AND(E15<>"",E15>Vencimentos!D7),F15*0.02,0) -> 0 | Q15: =IF(AND(E15<>"",E15>Vencimentos!D7),F15*0.00033*(E15-Vencimentos!D7),0) -> 0
B16: 6 | C16: 2021 | D16: SET | E16: 44449 | F16: =Reajustes!H4 -> 1351.05 | G16: 1392.72 | H16: =O15-IF(G16="",0,G16) -> 153769.92 | I16: ='Índices IPCA'!C10 -> 5944.21 | J16: ='Índices IPCA'!D10 -> 0.011599629 | L16: =H16 -> 153769.92 | N16: =H16 -> 153769.92 | O16: =H16 -> 153769.92 | P16: =IF(AND(E16<>"",E16>Vencimentos!D8),F16*0.02,0) -> 0 | Q16: =IF(AND(E16<>"",E16>Vencimentos!D8),F16*0.00033*(E16-Vencimentos!D8),0) -> 0
B17: 7 | C17: 2021 | D17: OUT | E17: 44480 | F17: =Reajustes!H4 -> 1351.05 | G17: 1392.72 | H17: =O16-IF(G17="",0,G17) -> 152377.2 | I17: ='Índices IPCA'!C11 -> 6018.51 | J17: ='Índices IPCA'!D11 -> 0.012499558 | L17: =H17 -> 152377.2 | N17: =H17 -> 152377.2 | O17: =H17 -> 152377.2 | P17: =IF(AND(E17<>"",E17>Vencimentos!D9),F17*0.02,0) -> 0 | Q17: =IF(AND(E17<>"",E17>Vencimentos!D9),F17*0.00033*(E17-Vencimentos!D9),0) -> 0
B18: 8 | C18: 2021 | D18: NOV | E18: 44510 | F18: =Reajustes!H4 -> 1351.05 | G18: 1392.72 | H18: =O17-IF(G18="",0,G18) -> 150984.48 | I18: ='Índices IPCA'!C12 -> 6075.69 | J18: ='Índices IPCA'!D12 -> 0.0095006904 | L18: =H18 -> 150984.48 | N18: =H18 -> 150984.48 | O18: =H18 -> 150984.48 | P18: =IF(AND(E18<>"",E18>Vencimentos!D10),F18*0.02,0) -> 0 | Q18: =IF(AND(E18<>"",E18>Vencimentos!D10),F18*0.00033*(E18-Vencimentos!D10),0) -> 0
B19: 9 | C19: 2021 | D19: DEZ | E19: 44540 | F19: =Reajustes!H4 -> 1351.05 | G19: 1392.72 | H19: =O18-IF(G19="",0,G19) -> 149591.76 | I19: ='Índices IPCA'!C13 -> 6120.04 | J19: ='Índices IPCA'!D13 -> 0.0072995824 | L19: =H19 -> 149591.76 | N19: =H19 -> 149591.76 | O19: =H19 -> 149591.76 | P19: =IF(AND(E19<>"",E19>Vencimentos!D11),F19*0.02,0) -> 0 | Q19: =IF(AND(E19<>"",E19>Vencimentos!D11),F19*0.00033*(E19-Vencimentos!D11),0) -> 0 | S19: 5000
B20: 10 | C20: 2022 | D20: JAN | E20: 44572 | F20: =Reajustes!H4 -> 1351.05 | G20: 1392.72 | H20: =O19-IF(G20="",0,G20) -> 148199.04 | I20: ='Índices IPCA'!C14 -> 6153.09 | J20: ='Índices IPCA'!D14 -> 0.0054002915 | L20: =H20 -> 148199.04 | N20: =H20 -> 148199.04 | O20: =H20 -> 148199.04 | P20: =IF(AND(E20<>"",E20>Vencimentos!D12),F20*0.02,0) -> 27.021 | Q20: =IF(AND(E20<>"",E20>Vencimentos!D12),F20*0.00033*(E20-Vencimentos!D12),0) -> 0.4458465
B21: 11 | C21: 2022 | D21: FEV | E21: 44602 | F21: =Reajustes!H4 -> 1351.05 | G21: 1392.72 | H21: =O20-IF(G21="",0,G21) -> 146806.32 | I21: ='Índices IPCA'!C15 -> 6215.24 | J21: ='Índices IPCA'!D15 -> 0.010100616 | L21: =H21 -> 146806.32 | N21: =H21 -> 146806.32 | O21: =H21 -> 146806.32 | P21: =IF(AND(E21<>"",E21>Vencimentos!D13),F21*0.02,0) -> 0 | Q21: =IF(AND(E21<>"",E21>Vencimentos!D13),F21*0.00033*(E21-Vencimentos!D13),0) -> 0
B22: 12 | C22: 2022 | D22: MAR | E22: 44630 | F22: =Reajustes!H4 -> 1351.05 | G22: 1392.72 | H22: =O21-IF(G22="",0,G22) -> 145413.6 | I22: ='Índices IPCA'!C16 -> 6315.93 | J22: ='Índices IPCA'!D16 -> 0.016200501 | K22: =Reajustes!F4 -> 0.11299412 | L22: =IF(K22=0,H22,H22*(1+K22)) -> 161844.48 | M22: =Reajustes!E5 -> 0.10690623 | N22: =L22*(1+M22) -> 179146.66 | O22: =N22 -> 179146.66 | P22: =IF(AND(E22<>"",E22>Vencimentos!D14),F22*0.02,0) -> 0 | Q22: =IF(AND(E22<>"",E22>Vencimentos!D14),F22*0.00033*(E22-Vencimentos!D14),0) -> 0
B23: 13 | C23: 2022 | D23: ABR | E23: 44662 | F23: =Reajustes!H5 -> 1664.4667 | G23: 1392.72 | H23: =O22-IF(G23="",0,G23) -> 177753.94 | I23: ='Índices IPCA'!C17 -> 6382.88 | J23: ='Índices IPCA'!D17 -> 0.010600181 | L23: =H23 -> 177753.94 | N23: =H23 -> 177753.94 | O23: =H23 -> 177753.94 | P23: =IF(AND(E23<>"",E23>Vencimentos!D15),F23*0.02,0) -> 0 | Q23: =IF(AND(E23<>"",E23>Vencimentos!D15),F23*0.00033*(E23-Vencimentos!D15),0) -> 0 | R23: =Reajustes!I21 -> 45000
B24: 14 | C24: 2022 | D24: MAI | E24: 44691 | F24: =Reajustes!H5 -> 1664.4667 | G24: 1392.72 | H24: =O23-IF(G24="",0,G24) -> 176361.22 | I24: ='Índices IPCA'!C18 -> 6412.88 | J24: ='Índices IPCA'!D18 -> 0.0047000727 | L24: =H24 -> 176361.22 | N24: =H24 -> 176361.22 | O24: =H24 -> 176361.22 | P24: =IF(AND(E24<>"",E24>Vencimentos!D16),F24*0.02,0) -> 0 | Q24: =IF(AND(E24<>"",E24>Vencimentos!D16),F24*0.00033*(E24-Vencimentos!D16),0) -> 0
B25: 15 | C25: 2022 | D25: JUN | E25: 44726 | F25: =Reajustes!H5 -> 1664.4667 | G25: 1392.72 | H25: =O24-IF(G25="",0,G25) -> 174968.5 | I25: ='Índices IPCA'!C19 -> 6455.85 | J25: ='Índices IPCA'!D19 -> 0.0067005776 | L25: =H25 -> 174968.5 | N25: =H25 -> 174968.5 | O25: =H25 -> 174968.5 | P25: =IF(AND(E25<>"",E25>Vencimentos!D17),F25*0.02,0) -> 33.289335 | Q25: =IF(AND(E25<>"",E25>Vencimentos!D17),F25*0.00033*(E25-Vencimentos!D17),0) -> 2.1970961
B26: 16 | C26: 2022 | D26: JUL | E26: 44783 | F26: =Reajustes!H5 -> 1664.4667 | G26: 1392.72 | H26: =O25-IF(G26="",0,G26) -> 173575.78 | I26: ='Índices IPCA'!C20 -> 6411.95 | J26: ='Índices IPCA'!D20 -> -0.0068000341 | L26: =H26 -> 173575.78 | N26: =H26 -> 173575.78 | O26: =H26 -> 173575.78 | P26: =IF(AND(E26<>"",E26>Vencimentos!D18),F26*0.02,0) -> 33.289335 | Q26: =IF(AND(E26<>"",E26>Vencimentos!D18),F26*0.00033*(E26-Vencimentos!D18),0) -> 16.478221
B27: 17 | C27: 2022 | D27: AGO | E27: 44844 | F27: =Reajustes!H5 -> 1664.4667 | G27: 1392.72 | H27: =O26-IF(G27="",0,G27) -> 172183.06 | I27: ='Índices IPCA'!C21 -> 6388.87 | J27: ='Índices IPCA'!D21 -> -0.003599529 | L27: =H27 -> 172183.06 | N27: =H27 -> 172183.06 | O27: =H27 -> 172183.06 | P27: =IF(AND(E27<>"",E27>Vencimentos!D19),F27*0.02,0) -> 33.289335 | Q27: =IF(AND(E27<>"",E27>Vencimentos!D19),F27*0.00033*(E27-Vencimentos!D19),0) -> 33.505716
B28: 18 | C28: 2022 | D28: SET | E28: 44876 | F28: =Reajustes!H5 -> 1664.4667 | G28: 1392.72 | H28: =O27-IF(G28="",0,G28) -> 170790.34 | I28: ='Índices IPCA'!C22 -> 6370.34 | J28: ='Índices IPCA'!D22 -> -0.0029003564 | L28: =H28 -> 170790.34 | N28: =H28 -> 170790.34 | O28: =H28 -> 170790.34 | P28: =IF(AND(E28<>"",E28>Vencimentos!D20),F28*0.02,0) -> 33.289335 | Q28: =IF(AND(E28<>"",E28>Vencimentos!D20),F28*0.00033*(E28-Vencimentos!D20),0) -> 32.956442
B29: 19 | C29: 2022 | D29: OUT | E29: 44908 | F29: =Reajustes!H5 -> 1664.4667 | G29: 1351.05 | H29: =O28-IF(G29="",0,G29) -> 169439.29 | I29: ='Índices IPCA'!C23 -> 6407.93 | J29: ='Índices IPCA'!D23 -> 0.0059007839 | L29: =H29 -> 169439.29 | N29: =H29 -> 169439.29 | O29: =H29 -> 169439.29 | P29: =IF(AND(E29<>"",E29>Vencimentos!D21),F29*0.02,0) -> 33.289335 | Q29: =IF(AND(E29<>"",E29>Vencimentos!D21),F29*0.00033*(E29-Vencimentos!D21),0) -> 35.153538 | S29: 5000
B30: 20 | C30: 2022 | D30: NOV | E30: 44937 | F30: =Reajustes!H5 -> 1664.4667 | G30: 1392.72 | H30: =O29-IF(G30="",0,G30) -> 168046.57 | I30: ='Índices IPCA'!C24 -> 6434.2 | J30: ='Índices IPCA'!D24 -> 0.0040996078 | L30: =H30 -> 168046.57 | N30: =H30 -> 168046.57 | O30: =H30 -> 168046.57 | P30: =IF(AND(E30<>"",E30>Vencimentos!D22),F30*0.02,0) -> 33.289335 | Q30: =IF(AND(E30<>"",E30>Vencimentos!D22),F30*0.00033*(E30-Vencimentos!D22),0) -> 34.05499
B31: 21 | C31: 2022 | D31: DEZ | E31: 44968 | F31: =Reajustes!H5 -> 1664.4667 | G31: 1500 | H31: =O30-IF(G31="",0,G31) -> 166546.57 | I31: ='Índices IPCA'!C25 -> 6474.09 | J31: ='Índices IPCA'!D25 -> 0.0061996829 | L31: =H31 -> 166546.57 | N31: =H31 -> 166546.57 | O31: =H31 -> 166546.57 | P31: =IF(AND(E31<>"",E31>Vencimentos!D23),F31*0.02,0) -> 33.289335 | Q31: =IF(AND(E31<>"",E31>Vencimentos!D23),F31*0.00033*(E31-Vencimentos!D23),0) -> 33.505716
B32: 22 | C32: 2023 | D32: JAN | E32: 44998 | F32: =Reajustes!H5 -> 1664.4667 | G32: 2000 | H32: =O31-IF(G32="",0,G32) -> 164546.57 | I32: ='Índices IPCA'!C26 -> 6508.4 | J32: ='Índices IPCA'!D26 -> 0.0052995865 | L32: =H32 -> 164546.57 | N32: =H32 -> 164546.57 | O32: =H32 -> 164546.57 | P32: =IF(AND(E32<>"",E32>Vencimentos!D24),F32*0.02,0) -> 33.289335 | Q32: =IF(AND(E32<>"",E32>Vencimentos!D24),F32*0.00033*(E32-Vencimentos!D24),0) -> 34.05499
B33: 23 | C33: 2023 | D33: FEV | E33: 45028 | F33: =Reajustes!H5 -> 1664.4667 | G33: 1500 | H33: =O32-IF(G33="",0,G33) -> 163046.57 | I33: ='Índices IPCA'!C27 -> 6563.07 | J33: ='Índices IPCA'!D27 -> 0.008399914 | L33: =H33 -> 163046.57 | N33: =H33 -> 163046.57 | O33: =H33 -> 163046.57 | P33: =IF(AND(E33<>"",E33>Vencimentos!D25),F33*0.02,0) -> 33.289335 | Q33: =IF(AND(E33<>"",E33>Vencimentos!D25),F33*0.00033*(E33-Vencimentos!D25),0) -> 33.505716
B34: 24 | C34: 2023 | D34: MAR | E34: 45056 | F34: =Reajustes!H5 -> 1664.4667 | G34: 1500 | H34: =O33-IF(G34="",0,G34) -> 161546.57 | I34: ='Índices IPCA'!C28 -> 6609.67 | J34: ='Índices IPCA'!D28 -> 0.0071003357 | K34: =Reajustes!F5 -> 0.046507799 | L34: =IF(K34=0,H34,H34*(1+K34)) -> 169059.75 | M34: =Reajustes!E6 -> 0.10690623 | N34: =L34*(1+M34) -> 187133.29 | O34: =N34 -> 187133.29 | P34: =IF(AND(E34<>"",E34>Vencimentos!D26),F34*0.02,0) -> 33.289335 | Q34: =IF(AND(E34<>"",E34>Vencimentos!D26),F34*0.00033*(E34-Vencimentos!D26),0) -> 33.505716
B35: 25 | C35: 2023 | D35: ABR | E35: 45085 | F35: =Reajustes!H6 -> 1928.095 | G35: 1500 | H35: =O34-IF(G35="",0,G35) -> 185633.29 | I35: ='Índices IPCA'!C29 -> 6649.99 | J35: ='Índices IPCA'!D29 -> 0.0061001533 | L35: =H35 -> 185633.29 | N35: =H35 -> 185633.29 | O35: =H35 -> 185633.29 | P35: =IF(AND(E35<>"",E35>Vencimentos!D27),F35*0.02,0) -> 38.561899 | Q35: =IF(AND(E35<>"",E35>Vencimentos!D27),F35*0.00033*(E35-Vencimentos!D27),0) -> 37.540009 | R35: =Reajustes!I22 -> 46335.44
B36: 26 | C36: 2023 | D36: MAI | E36: 45118 | F36: =Reajustes!H6 -> 1928.095 | G36: 1500 | H36: =O35-IF(G36="",0,G36) -> 184133.29 | I36: ='Índices IPCA'!C30 -> 6665.28 | J36: ='Índices IPCA'!D30 -> 0.0022992516 | L36: =H36 -> 184133.29 | N36: =H36 -> 184133.29 | O36: =H36 -> 184133.29 | P36: =IF(AND(E36<>"",E36>Vencimentos!D28),F36*0.02,0) -> 38.561899 | Q36: =IF(AND(E36<>"",E36>Vencimentos!D28),F36*0.00033*(E36-Vencimentos!D28),0) -> 39.448823
B37: 27 | C37: 2023 | D37: JUN | E37: 45148 | F37: =Reajustes!H6 -> 1928.095 | G37: 1500 | H37: =O36-IF(G37="",0,G37) -> 182633.29 | I37: ='Índices IPCA'!C31 -> 6659.95 | J37: ='Índices IPCA'!D31 -> -0.00079966633 | L37: =H37 -> 182633.29 | N37: =H37 -> 182633.29 | O37: =H37 -> 182633.29 | P37: =IF(AND(E37<>"",E37>Vencimentos!D29),F37*0.02,0) -> 38.561899 | Q37: =IF(AND(E37<>"",E37>Vencimentos!D29),F37*0.00033*(E37-Vencimentos!D29),0) -> 37.540009
B38: 28 | C38: 2023 | D38: JUL | E38: 45182 | F38: =Reajustes!H6 -> 1928.095 | G38: 1500 | H38: =O37-IF(G38="",0,G38) -> 181133.29 | I38: ='Índices IPCA'!C32 -> 6667.94 | J38: ='Índices IPCA'!D32 -> 0.0011997087 | L38: =H38 -> 181133.29 | N38: =H38 -> 181133.29 | O38: =H38 -> 181133.29 | P38: =IF(AND(E38<>"",E38>Vencimentos!D30),F38*0.02,0) -> 38.561899 | Q38: =IF(AND(E38<>"",E38>Vencimentos!D30),F38*0.00033*(E38-Vencimentos!D30),0) -> 41.357637
B39: 29 | C39: 2023 | D39: AGO | F39: =Reajustes!H6 -> 1928.095 | H39: =O38-IF(G39="",0,G39) -> 181133.29 | I39: ='Índices IPCA'!C33 -> 6683.28 | J39: ='Índices IPCA'!D33 -> 0.0023005606 | L39: =H39 -> 181133.29 | N39: =H39 -> 181133.29 | O39: =H39 -> 181133.29 | P39: =IF(AND(E39<>"",E39>Vencimentos!D31),F39*0.02,0) -> 0 | Q39: =IF(AND(E39<>"",E39>Vencimentos!D31),F39*0.00033*(E39-Vencimentos!D31),0) -> 0
B40: 30 | C40: 2023 | D40: SET | F40: =Reajustes!H6 -> 1928.095 | H40: =O39-IF(G40="",0,G40) -> 181133.29 | I40: ='Índices IPCA'!C34 -> 6700.66 | J40: ='Índices IPCA'!D34 -> 0.0026005195 | L40: =H40 -> 181133.29 | N40: =H40 -> 181133.29 | O40: =H40 -> 181133.29 | P40: =IF(AND(E40<>"",E40>Vencimentos!D32),F40*0.02,0) -> 0 | Q40: =IF(AND(E40<>"",E40>Vencimentos!D32),F40*0.00033*(E40-Vencimentos!D32),0) -> 0
B41: 31 | C41: 2023 | D41: OUT | F41: =Reajustes!H6 -> 1928.095 | H41: =O40-IF(G41="",0,G41) -> 181133.29 | I41: ='Índices IPCA'!C35 -> 6716.74 | J41: ='Índices IPCA'!D35 -> 0.0023997636 | L41: =H41 -> 181133.29 | N41: =H41 -> 181133.29 | O41: =H41 -> 181133.29 | P41: =IF(AND(E41<>"",E41>Vencimentos!D33),F41*0.02,0) -> 0 | Q41: =IF(AND(E41<>"",E41>Vencimentos!D33),F41*0.00033*(E41-Vencimentos!D33),0) -> 0
B42: 32 | C42: 2023 | D42: NOV | F42: =Reajustes!H6 -> 1928.095 | H42: =O41-IF(G42="",0,G42) -> 181133.29 | I42: ='Índices IPCA'!C36 -> 6735.55 | J42: ='Índices IPCA'!D36 -> 0.0028004657 | L42: =H42 -> 181133.29 | N42: =H42 -> 181133.29 | O42: =H42 -> 181133.29 | P42: =IF(AND(E42<>"",E42>Vencimentos!D34),F42*0.02,0) -> 0 | Q42: =IF(AND(E42<>"",E42>Vencimentos!D34),F42*0.00033*(E42-Vencimentos!D34),0) -> 0
...

Sheet Índices IPCA
A1: SÉRIE HISTÓRICA IPCA - IBGE
A2: Fonte: IBGE | Atualizado até MAR/2026 | Início: MAR/2021 (mês do contrato)
A3: ANO | B3: MÊS | C3: NÚM. ÍNDICE | D3: VAR. MENSAL | E3: VAR. ACUM. DESDE MAR/21
A4: 2021 | B4: MAR | C4: 5674.72 | E4: 0
A5: 2021 | B5: ABR | C5: 5692.31 | D5: =(C5-C4)/C4 -> 0.0030997124 | E5: =C5/C$4-1 -> 0.0030997124
A6: 2021 | B6: MAI | C6: 5739.56 | D6: =(C6-C5)/C5 -> 0.0083006723 | E6: =C6/C$4-1 -> 0.011426114
A7: 2021 | B7: JUN | C7: 5769.98 | D7: =(C7-C6)/C6 -> 0.0053000578 | E7: =C7/C$4-1 -> 0.016786731
A8: 2021 | B8: JUL | C8: 5825.37 | D8: =(C8-C7)/C7 -> 0.0095996867 | E8: =C8/C$4-1 -> 0.026547565
A9: 2021 | B9: AGO | C9: 5876.05 | D9: =(C9-C8)/C8 -> 0.0086998766 | E9: =C9/C$4-1 -> 0.035478402
A10: 2021 | B10: SET | C10: 5944.21 | D10: =(C10-C9)/C9 -> 0.011599629 | E10: =C10/C$4-1 -> 0.047489568
A11: 2021 | B11: OUT | C11: 6018.51 | D11: =(C11-C10)/C10 -> 0.012499558 | E11: =C11/C$4-1 -> 0.060582725
A12: 2021 | B12: NOV | C12: 6075.69 | D12: =(C12-C11)/C11 -> 0.0095006904 | E12: =C12/C$4-1 -> 0.070658993
A13: 2021 | B13: DEZ | C13: 6120.04 | D13: =(C13-C12)/C12 -> 0.0072995824 | E13: =C13/C$4-1 -> 0.078474356
A14: 2022 | B14: JAN | C14: 6153.09 | D14: =(C14-C13)/C13 -> 0.0054002915 | E14: =C14/C$4-1 -> 0.084298432
A15: 2022 | B15: FEV | C15: 6215.24 | D15: =(C15-C14)/C14 -> 0.010100616 | E15: =C15/C$4-1 -> 0.095250515
A16: 2022 | B16: MAR | C16: 6315.93 | D16: =(C16-C15)/C15 -> 0.016200501 | E16: =C16/C$4-1 -> 0.11299412
... A64: 2026 | B64: MAR | C64: 7545.54 | D64: =(C64-C63)/C63 -> 0.0087997946 | E64: =C64/C$4-1 -> 0.32967618

Sheet Reajustes
A1: PARÂMETROS DE REAJUSTE ANUAL — PARCELAS MENSAIS
A2: Cláusula 2.2.1 — Correção: IPCA acumulado 12 meses + Juros compostos 0,85% a.m.
A3: ANO CONTRATUAL | B3: PARCELAS | C3: PERÍODO | D3: JUROS a.m. | E3: JUROS COMP. 12 MESES | F3: IPCA ACUM 12 MESES | G3: FATOR CORREÇÃO | H3: PARCELA MENSAL (R$)
A4: 1º ANO | B4: 1-12 | C4: ABR/21 a MAR/22 | D4: 0.0085 | E4: =(1+D4)^12-1 -> 0.10690623 | F4: ='Índices IPCA'!C16/'Índices IPCA'!C4-1 -> 0.11299412 | G4: 1 | H4: 1351.05
A5: 2º ANO | B5: 13-24 | C5: ABR/22 a MAR/23 | D5: 0.0085 | E5: =(1+D5)^12-1 -> 0.10690623 | F5: ='Índices IPCA'!C28/'Índices IPCA'!C16-1 -> 0.046507799 | G5: =IF(F4=0,1,(1+F4)*(1+E5)) -> 1.2319801 | H5: =H4*G5 -> 1664.4667
A6: 3º ANO | B6: 25-36 | C6: ABR/23 a MAR/24 | D6: 0.0085 | E6: =(1+D6)^12-1 -> 0.10690623 | F6: ='Índices IPCA'!C40/'Índices IPCA'!C28-1 -> 0.03925612 | G6: =IF(F5=0,1,(1+F5)*(1+E6)) -> 1.158386 | H6: =H5*G6 -> 1928.095
A7: 4º ANO | B7: 37-48 | C7: ABR/24 a MAR/25 | D7: 0.0085 | E7: =(1+D7)^12-1 -> 0.10690623 | F7: ='Índices IPCA'!C52/'Índices IPCA'!C40-1 -> 0.054772504 | G7: =IF(F6=0,1,(1+F6)*(1+E7)) -> 1.1503591 | H7: =H6*G7 -> 2218.0015
A8: 5º ANO | B8: 49-60 | C8: ABR/25 a MAR/26 | D8: 0.0085 | E8: =(1+D8)^12-1 -> 0.10690623 | F8: ='Índices IPCA'!C64/'Índices IPCA'!C52-1 -> 0.041427779 | G8: =IF(F7=0,1,(1+F7)*(1+E8)) -> 1.1675343 | H8: =H7*G8 -> 2589.5928
A9: 6º ANO | B9: 61-72 | C9: ABR/26 a MAR/27 | D9: 0.0085 | E9: =(1+D9)^12-1 -> 0.10690623 | F9: 0 | G9: =IF(F8=0,1,(1+F8)*(1+E9)) -> 1.1527629 | H9: =H8*G9 -> 2985.1865
A10: 7º ANO | B10: 73-84 | C10: ABR/27 a MAR/28 | D10: 0.0085 | E10: =(1+D10)^12-1 -> 0.10690623 | F10: 0 | G10: =IF(F9=0,1,(1+F9)*(1+E10)) -> 1 | H10: =H9*G10 -> 2985.1865
A11: 8º ANO | B11: 85-96 | C11: ABR/28 a MAR/29 | D11: 0.0085 | E11: =(1+D11)^12-1 -> 0.10690623 | F11: 0 | G11: =IF(F10=0,1,(1+F10)*(1+E11)) -> 1 | H11: =H10*G11 -> 2985.1865
A12: 9º ANO | B12: 97-108 | C12: ABR/29 a MAR/30 | D12: 0.0085 | E12: =(1+D12)^12-1 -> 0.10690623 | F12: 0 | G12: =IF(F11=0,1,(1+F11)*(1+E12)) -> 1 | H12: =H11*G12 -> 2985.1865
A13: 10º ANO | B13: 109-120 | C13: ABR/30 a MAR/31 | D13: 0.0085 | E13: =(1+D13)^12-1 -> 0.10690623 | F13: 0 | G13: =IF(F12=0,1,(1+F12)*(1+E13)) -> 1 | H13: =H12*G13 -> 2985.1865
A16: SALDO REMANESCENTE — PARCELAS ANUAIS (Cláusula 2.2.2)
A17: Dívida: R$ 50.000 | 10 parcelas anuais | 1º reajuste: ABR/2023 | Ordem: Pagamento → Reajuste
A18: Saldo Inicial (ABR/2022): | F18: 50000
A20: Nº | B20: ANIVERSÁRIO | C20: SALDO INICIAL | D20: PAGAMENTO | E20: APÓS PAGAMENTO | F20: IPCA ACUM 12 MESES | G20: JUROS COMP. 12 MESES | H20: REAJUSTE? | I20: SALDO REMANESCENTE
A21: 1 | B21: ABR/2022 | C21: =F18 -> 50000 | D21: 5000 | E21: =C21-D21 -> 45000 | H21: NÃO | I21: =E21 -> 45000
A22: 2 | B22: ABR/2023 | C22: =I21 -> 45000 | D22: 5000 | E22: =C22-D22 -> 40000 | F22: ='Índices IPCA'!C28/'Índices IPCA'!C16-1 -> 0.046507799 | G22: =(1+0.0085)^12-1 -> 0.10690623 | H22: SIM | I22: =IF(F22=0,E22*(1+G22),E22*(1+F22)*(1+G22)) -> 46335.44
A23: 3 | B23: ABR/2024 | C23: =I22 -> 46335.44 | D23: 0 | E23: =C23-D23 -> 46335.44 | F23: ='Índices IPCA'!C40/'Índices IPCA'!C28-1 -> 0.03925612 | G23: =(1+0.0085)^12-1 -> 0.10690623 | H23: SIM | I23: =IF(F23=0,E23*(1+G23),E23*(1+F23)*(1+G23)) -> 53302.394
A24: 4 | B24: ABR/2025 | C24: =I23 -> 53302.394 | D24: 0 | E24: =C24-D24 -> 53302.394 | F24: ='Índices IPCA'!C52/'Índices IPCA'!C40-1 -> 0.054772504 | G24: =(1+0.0085)^12-1 -> 0.10690623 | H24: SIM | I24: =IF(F24=0,E24*(1+G24),E24*(1+F24)*(1+G24)) -> 62232.37
A25: 5 | B25: ABR/2026 | C25: =I24 -> 62232.37 | D25: 0 | E25: =C25-D25 -> 62232.37 | F25: ='Índices IPCA'!C64/'Índices IPCA'!C52-1 -> 0.041427779 | G25: =(1+0.0085)^12-1 -> 0.10690623 | H25: SIM | I25: =IF(F25=0,E25*(1+G25),E25*(1+F25)*(1+G25)) -> 71739.167
A26: 6 | B26: ABR/2027 | C26: =I25 -> 71739.167 | D26: 0 | E26: =C26-D26 -> 71739.167 | F26: 0 | G26: =(1+0.0085)^12-1 -> 0.10690623 | H26: SIM | I26: =IF(F26=0,E26*(1+G26),E26*(1+F26)*(1+G26)) -> 79408.531
A27: 7 | B27: ABR/2028 | C27: =I26 -> 79408.531 | D27: 0 | E27: =C27-D27 -> 79408.531 | F27: 0 | G27: =(1+0.0085)^12-1 -> 0.10690623 | H27: SIM | I27: =IF(F27=0,E27*(1+G27),E27*(1+F27)*(1+G27)) -> 87897.797
A28: 8 | B28: ABR/2029 | C28: =I27 -> 87897.797 | D28: 0 | E28: =C28-D28 -> 87897.797 | F28: 0 | G28: =(1+0.0085)^12-1 -> 0.10690623 | H28: SIM | I28: =IF(F28=0,E28*(1+G28),E28*(1+F28)*(1+G28)) -> 97294.619
A29: 9 | B29: ABR/2030 | C29: =I28 -> 97294.619 | D29: 0 | E29: =C29-D29 -> 97294.619 | F29: 0 | G29: =(1+0.0085)^12-1 -> 0.10690623 | H29: SIM | I29: =IF(F29=0,E29*(1+G29),E29*(1+F29)*(1+G29)) -> 107696.02
A30: 10 | B30: ABR/2031 | C30: =I29 -> 107696.02 | D30: 0 | E30: =C30-D30 -> 107696.02 | F30: 0 | G30: =(1+0.0085)^12-1 -> 0.10690623 | H30: SIM | I30: =IF(F30=0,E30*(1+G30),E30*(1+F30)*(1+G30)) -> 119209.4
A31: TOTAIS | D31: =SUM(D21:D30) -> 10000
A33: SALDO REMANESCENTE ATUALIZADO: | I33: =I30 -> 119209.4
A34: Total pago (parcelas anuais): | I34: =D31 -> 10000
A36: NOTAS:
A37: ABR/2022: 1ª parcela devida, SEM reajuste — saldo = R$ 50.000 - R$ 5.000 = R$ 45.000
A38: ABR/2023: 1º REAJUSTE — primeiro paga, depois corrige o saldo pelo IPCA + juros
A39: Parcela 1 paga em DEZ/2021 | Parcela 2 paga em DEZ/2022 | Parcelas 3-10 não pagas
A40: Parcelas 6-10: sem IPCA divulgado — correção apenas por juros compostos 0,85% a.m.

Sheet Vencimentos
A1: VENCIMENTOS AJUSTADOS — DIAS ÚTEIS E FERIADOS
A2: PARCELA | B2: MÊS/ANO | C2: VENC. ORIGINAL | D2: VENC. ÚTIL | E2: FERIADO/ FIM SEMANA? | F2: OBSERVAÇÃO
A3: 1 | B3: ABR/2021 | C3: 44296 | D3: 44298 | E3: SIM | F3: Sábado
A4: 2 | B4: MAI/2021 | C4: 44326 | D4: 44326
A5: 3 | B5: JUN/2021 | C5: 44357 | D5: 44357
A6: 4 | B6: JUL/2021 | C6: 44387 | D6: 44389 | E6: SIM | F6: Sábado
A7: 5 | B7: AGO/2021 | C7: 44418 | D7: 44418
A8: 6 | B8: SET/2021 | C8: 44449 | D8: 44449
A9: 7 | B9: OUT/2021 | C9: 44479 | D9: 44480 | E9: SIM | F9: Domingo
A10: 8 | B10: NOV/2021 | C10: 44510 | D10: 44510
A11: 9 | B11: DEZ/2021 | C11: 44540 | D11: 44540
A12: 10 | B12: JAN/2022 | C12: 44571 | D12: 44571
A13: 11 | B13: FEV/2022 | C13: 44602 | D13: 44602
A14: 12 | B14: MAR/2022 | C14: 44630 | D14: 44630
A15: 13 | B15: ABR/2022 | C15: 44661 | D15: 44662 | E15: SIM | F15: Domingo
A16: 14 | B16: MAI/2022 | C16: 44691 | D16: 44691
A17: 15 | B17: JUN/2022 | C17: 44722 | D17: 44722
A18: 16 | B18: JUL/2022 | C18: 44752 | D18: 44753 | E18: SIM | F18: Domingo
A19: 17 | B19: AGO/2022 | C19: 44783 | D19: 44783
A20: 18 | B20: SET/2022 | C20: 44814 | D20: 44816 | E20: SIM | F20: Sábado
A21: 19 | B21: OUT/2022 | C21: 44844 | D21: 44844
A22: 20 | B22: NOV/2022 | C22: 44875 | D22: 44875
A23: 21 | B23: DEZ/2022 | C23: 44905 | D23: 44907 | E23: SIM | F23: Sábado
A24: 22 | B24: JAN/2023 | C24: 44936 | D24: 44936
A25: 23 | B25: FEV/2023 | C25: 44967 | D25: 44967
A26: 24 | B26: MAR/2023 | C26: 44995 | D26: 44995
A27: 25 | B27: ABR/2023 | C27: 45026 | D27: 45026
A28: 26 | B28: MAI/2023 | C28: 45056 | D28: 45056
A29: 27 | B29: JUN/2023 | C29: 45087 | D29: 45089 | E29: SIM | F29: Sábado
A30: 28 | B30: JUL/2023 | C30: 45117 | D30: 45117
A31: 29 | B31: AGO/2023 | C31: 45148 | D31: 45148
A32: 30 | B32: SET/2023 | C32: 45179 | D32: 45180 | E32: SIM | F32: Domingo
A33: 31 | B33: OUT/2023 | C33: 45209 | D33: 45209
A34: 32 | B34: NOV/2023 | C34: 45240 | D34: 45240
A35: 33 | B35: DEZ/2023 | C35: 45270 | D35: 45271 | E35: SIM | F35: Domingo
A36: 34 | B36: JAN/2024 | C36: 45301 | D36: 45301
A37: 35 | B37: FEV/2024 | C37: 45332 | D37: 45334 | E37: SIM | F37: Sábado
A38: 36 | B38: MAR/2024 | C38: 45361 | D38: 45362 | E38: SIM | F38: Domingo
A39: 37 | B39: ABR/2024 | C39: 45392 | D39: 45392
A40: 38 | B40: MAI/2024 | C40: 45422 | D40: 45422
...

Sheet Saldo Devedor Atualizado
A1: ATUALIZAÇÃO DO SALDO DEVEDOR — METODOLOGIA CÁLCULO EXATO
A2: Saldo corrigido anualmente: Saldo → (-) Pagamentos do Período → IPCA acum 12M → Juros comp. 0,85% a.m.
A4: PARCELAS MENSAIS (Cláusula 2.2.1) — Saldo Inicial: R$ 162.126,24
A6: ANO CONTRATUAL | B6: PERÍODO | C6: SALDO INICIAL | D6: PGTOS NO PERÍODO | E6: SALDO APÓS PAGAMENTOS | F6: IPCA ACUM 12 MESES (%) | G6: FATOR IPCA | H6: JUROS COMP. 12M (%) | I6: SALDO DEV. ATUALIZADO
A7: 1º ANO | B7: ABR/21-MAR/22 | C7: 162126.24 | D7: =SUM('Parcelas Mensais'!G11:G22) -> 16712.64 | E7: =C7-D7 -> 145413.6 | F7: 0.112993 | G7: =1+F7 -> 1.112993 | H7: =(1+0.0085)^12-1 -> 0.10690623 | I7: 179146.47
A8: 2º ANO | B8: ABR/22-MAR/23 | C8: =I7 -> 179146.47 | D8: =SUM('Parcelas Mensais'!G23:G34) -> 17600.09 | E8: =C8-D8 -> 161546.38 | F8: 0.046507 | G8: =1+F8 -> 1.046507 | H8: =(1+0.0085)^12-1 -> 0.10690623 | I8: 187132.87
A9: 3º ANO | B9: ABR/23-MAR/24 | C9: =I8 -> 187132.87 | D9: =SUM('Parcelas Mensais'!G35:G46) -> 6000 | E9: =C9-D9 -> 181132.87 | F9: 0.039256 | G9: =1+F9 -> 1.039256 | H9: =(1+0.0085)^12-1 -> 0.10690623 | I9: 208367.76
A10: 4º ANO | B10: ABR/24-MAR/25 | C10: =I9 -> 208367.76 | D10: =SUM('Parcelas Mensais'!G47:G58) -> 0 | E10: =C10-D10 -> 208367.76 | F10: 0.054772 | G10: =1+F10 -> 1.054772 | H10: =(1+0.0085)^12-1 -> 0.10690623 | I10: 243276.3
A11: 5º ANO | B11: ABR/25-MAR/26 | C11: =I10 -> 243276.3 | D11: =SUM('Parcelas Mensais'!G59:G70) -> 0 | E11: =C11-D11 -> 243276.3 | F11: 0.041428 | G11: =1+F11 -> 1.041428 | H11: =(1+0.0085)^12-1 -> 0.10690623 | I11: 280440.01
A12: 6º ANO | B12: ABR/26-MAR/27 | C12: =I11 -> 280440.01 | D12: =SUM('Parcelas Mensais'!G71:G82) -> 0 | E12: =C12-D12 -> 280440.01 | F12: 0 | G12: =1+F12 -> 1 | H12: =(1+0.0085)^12-1 -> 0.10690623 | I12: =ROUND(E12*G12,2)+ROUND(ROUND(E12*G12,2)*10.6906/100,2) -> 310420.73
A13: 7º ANO | B13: ABR/27-MAR/28 | C13: =I12 -> 310420.73 | D13: =SUM('Parcelas Mensais'!G83:G94) -> 0 | E13: =C13-D13 -> 310420.73 | F13: 0 | G13: =1+F13 -> 1 | H13: =(1+0.0085)^12-1 -> 0.10690623 | I13: =ROUND(E13*G13,2)+ROUND(ROUND(E13*G13,2)*10.6906/100,2) -> 343606.57
A14: 8º ANO | B14: ABR/28-MAR/29 | C14: =I13 -> 343606.57 | D14: =SUM('Parcelas Mensais'!G95:G106) -> 0 | E14: =C14-D14 -> 343606.57 | F14: 0 | G14: =1+F14 -> 1 | H14: =(1+0.0085)^12-1 -> 0.10690623 | I14: =ROUND(E14*G14,2)+ROUND(ROUND(E14*G14,2)*10.6906/100,2) -> 380340.17
A15: 9º ANO | B15: ABR/29-MAR/30 | C15: =I14 -> 380340.17 | D15: =SUM('Parcelas Mensais'!G107:G118) -> 0 | E15: =C15-D15 -> 380340.17 | F15: 0 | G15: =1+F15 -> 1 | H15: =(1+0.0085)^12-1 -> 0.10690623 | I15: =ROUND(E15*G15,2)+ROUND(ROUND(E15*G15,2)*10.6906/100,2) -> 421000.82
A16: 10º ANO | B16: ABR/30-MAR/31 | C16: =I15 -> 421000.82 | D16: =SUM('Parcelas Mensais'!G119:G130) -> 0 | E16: =C16-D16 -> 421000.82 | F16: 0 | G16: =1+F16 -> 1 | H16: =(1+0.0085)^12-1 -> 0.10690623 | I16: =ROUND(E16*G16,2)+ROUND(ROUND(E16*G16,2)*10.6906/100,2) -> 466008.33
A17: TOTAL PGTOS: | D17: =SUM(D7:D16) -> 40312.73 | H17: SALDO FINAL: | I17: =I16 -> 466008.33
A20: PARCELAS ANUAIS (Cláusula 2.2.2) — Saldo Inicial: R$ 50.000,00 | 1º reajuste ABR/2023
A22: Nº | B22: ANIVERSÁRIO | C22: SALDO INICIAL | D22: PAGAMENTO | E22: APÓS PAGAMENTO | F22: IPCA ACUM 12M (%) | G22: FATOR IPCA | H22: JUROS COMP. 12M (%) | I22: SALDO REMANESCENTE
A23: 1 | B23: ABR/2022 | C23: 50000 | D23: 5000 | E23: =C23-D23 -> 45000 | G23: 1 | I23: =E23 -> 45000
A24: 2 | B24: ABR/2023 | C24: =I23 -> 45000 | D24: 5000 | E24: =C24-D24 -> 40000 | F24: ='Índices IPCA'!C28/'Índices IPCA'!C16-1 -> 0.046507799 | G24: =1+F24 -> 1.0465078 | H24: =(1+0.0085)^12-1 -> 0.10690623 | I24: =IF(F24=0,E24*(1+H24),E24*G24*(1+H24)) -> 46335.44
A25: 3 | B25: ABR/2024 | C25: =I24 -> 46335.44 | D25: 0 | E25: =C25-D25 -> 46335.44 | F25: ='Índices IPCA'!C40/'Índices IPCA'!C28-1 -> 0.03925612 | G25: =1+F25 -> 1.0392561 | H25: =(1+0.0085)^12-1 -> 0.10690623 | I25: =IF(F25=0,E25*(1+H25),E25*G25*(1+H25)) -> 53302.394
A26: 4 | B26: ABR/2025 | C26: =I25 -> 53302.394 | D26: 0 | E26: =C26-D26 -> 53302.394 | F26: ='Índices IPCA'!C52/'Índices IPCA'!C40-1 -> 0.054772504 | G26: =1+F26 -> 1.0547725 | H26: =(1+0.0085)^12-1 -> 0.10690623 | I26: =IF(F26=0,E26*(1+H26),E26*G26*(1+H26)) -> 62232.37
A27: 5 | B27: ABR/2026 | C27: =I26 -> 62232.37 | D27: 0 | E27: =C27-D27 -> 62232.37 | F27: ='Índices IPCA'!C64/'Índices IPCA'!C52-1 -> 0.041427779 | G27: =1+F27 -> 1.0414278 | H27: =(1+0.0085)^12-1 -> 0.10690623 | I27: =IF(F27=0,E27*(1+H27),E27*G27*(1+H27)) -> 71739.167
A28: 6 | B28: ABR/2027 | C28: =I27 -> 71739.167 | D28: 0 | E28: =C28-D28 -> 71739.167 | F28: 0 | G28: =1+F28 -> 1 | H28: =(1+0.0085)^12-1 -> 0.10690623 | I28: =IF(F28=0,E28*(1+H28),E28*G28*(1+H28)) -> 79408.531
A29: 7 | B29: ABR/2028 | C29: =I28 -> 79408.531 | D29: 0 | E29: =C29-D29 -> 79408.531 | F29: 0 | G29: =1+F29 -> 1 | H29: =(1+0.0085)^12-1 -> 0.10690623 | I29: =IF(F29=0,E29*(1+H29),E29*G29*(1+H29)) -> 87897.797
A30: 8 | B30: ABR/2029 | C30: =I29 -> 87897.797 | D30: 0 | E30: =C30-D30 -> 87897.797 | F30: 0 | G30: =1+F30 -> 1 | H30: =(1+0.0085)^12-1 -> 0.10690623 | I30: =IF(F30=0,E30*(1+H30),E30*G30*(1+H30)) -> 97294.619
A31: 9 | B31: ABR/2030 | C31: =I30 -> 97294.619 | D31: 0 | E31: =C31-D31 -> 97294.619 | F31: 0 | G31: =1+F31 -> 1 | H31: =(1+0.0085)^12-1 -> 0.10690623 | I31: =IF(F31=0,E31*(1+H31),E31*G31*(1+H31)) -> 107696.02
A32: 10 | B32: ABR/2031 | C32: =I31 -> 107696.02 | D32: 0 | E32: =C32-D32 -> 107696.02 | F32: 0 | G32: =1+F32 -> 1 | H32: =(1+0.0085)^12-1 -> 0.10690623 | I32: =IF(F32=0,E32*(1+H32),E32*G32*(1+H32)) -> 119209.4
A33: TOTAL PGTOS: | D33: =SUM(D23:D32) -> 10000 | H33: SALDO FINAL: | I33: =I32 -> 119209.4
A35: DÍVIDA TOTAL ATUALIZADA
A36: Saldo Devedor Mensal: | I36: =I17 -> 466008.33
A37: Saldo Devedor Anual: | I37: =I33 -> 119209.4
A38: TOTAL DÍVIDA ATUALIZADA: | I38: =I36+I37 -> 585217.73
A39: Total pago (mensal + anual): | I39: =D17+D33 -> 50312.73
A41: METODOLOGIA (idêntica ao Cálculo Exato - calculoexato.com.br):
A42: 1. Toma o saldo devedor do período anterior
A43: 2. Subtrai os pagamentos EFETIVOS realizados no período (12 parcelas por ano contratual)
A44: 3. Aplica IPCA acumulado 12 meses (ABR a ABR)
A45: 4. Aplica juros compostos 0,85% a.m. (= 10,69060% em 12 meses)
A46: 5. Resultado = novo saldo devedor atualizado
A48: Os pagamentos são automaticamente puxados da aba "Parcelas Mensais" coluna G (Vlr Pago).
...

Sheet Mensais - Calc Exato
B1: CONTROLE — PARCELAS MENSAIS (Cálculo Exato)
B2: Saldo devedor: Saldo → (-) Pgto → Correção (IPCA+Juros separados, c/ arred. intermediário = método calculoexato.com.br)
B3: DADOS DO CONTRATO
B4: Compradora: | C4: UANDA SILVA CARVALHO | J4: CPF: | K4: 066.128.216-39
B5: Imóvel: | C5: Lote 16, Quadra D — Res. Parque das Nogueiras | J5: Data Contrato: | K5: 44279
B6: Saldo Mensal: | C6: 162126.24 | E6: Juros: | F6: 0,85% a.m. = 10,69060% em 12m | J6: Índice: | K6: IPCA (ABR a ABR)
B8: IDENTIFICAÇÃO | F8: VALORES (R$) | I8: IPCA | K8: CORREÇÃO ANUAL | P8: ENCARGOS ATRASO | R8: CLÁUS. 2.2.2
B9: Nº | C9: ANO | D9: MÊS | E9: DATA PGTO | F9: VLR A PAGAR (Saldo÷Rest) | G9: VLR PAGO | H9: SALDO BASE | I9: NÚM. ÍNDICE | J9: VAR. MENSAL | K9: IPCA ACUM 12M (%) | L9: VALOR ATUAL. IPCA (VA) | M9: JUROS COMP. 10,69060% | N9: SALDO DEV. VA + VJ | O9: SALDO DEVEDOR | P9: MULTA 2% | Q9: JUROS MORA 0,033%/dia | R9: SALDO REM. ANUAL | S9: ANUAL PAGO
B10: ENT. | C10: 2021 | D10: MAR | E10: 44279 | F10: 23569.58 | G10: 23569.58 | H10: 162126.24 | O10: =H10 -> 162126.24
B11: 1 | C11: 2021 | D11: ABR | E11: ='Parcelas Mensais'!E11 -> 44298 | F11: =H11/120 -> 1351.052 | G11: ='Parcelas Mensais'!G11 -> 1392.72 | H11: =O10 -> 162126.24 | I11: ='Parcelas Mensais'!I11 -> 5692.31 | J11: ='Parcelas Mensais'!J11 -> 0.0030997124 | L11: =O11 -> 160733.52 | N11: =O11 -> 160733.52 | O11: =H11-IF(G11="",0,G11) -> 160733.52 | P11: ='Parcelas Mensais'!P11 -> 0 | Q11: ='Parcelas Mensais'!Q11 -> 0
B12: 2 | C12: 2021 | D12: MAI | E12: ='Parcelas Mensais'!E12 -> 44323 | F12: =H12/119 -> 1350.7018 | G12: ='Parcelas Mensais'!G12 -> 1392.72 | H12: =O11 -> 160733.52 | I12: ='Parcelas Mensais'!I12 -> 5739.56 | J12: ='Parcelas Mensais'!J12 -> 0.0083006723 | L12: =O12 -> 159340.8 | N12: =O12 -> 159340.8 | O12: =H12-IF(G12="",0,G12) -> 159340.8 | P12: ='Parcelas Mensais'!P12 -> 0 | Q12: ='Parcelas Mensais'!Q12 -> 0
B13: 3 | C13: 2021 | D13: JUN | E13: ='Parcelas Mensais'!E13 -> 44357 | F13: =H13/118 -> 1350.3458 | G13: ='Parcelas Mensais'!G13 -> 1392.72 | H13: =O12 -> 159340.8 | I13: ='Parcelas Mensais'!I13 -> 5769.98 | J13: ='Parcelas Mensais'!J13 -> 0.0053000578 | L13: =O13 -> 157948.08 | N13: =O13 -> 157948.08 | O13: =H13-IF(G13="",0,G13) -> 157948.08 | P13: ='Parcelas Mensais'!P13 -> 0 | Q13: ='Parcelas Mensais'!Q13 -> 0
B14: 4 | C14: 2021 | D14: JUL | E14: ='Parcelas Mensais'!E14 -> 44386 | F14: =H14/117 -> 1349.9836 | G14: ='Parcelas Mensais'!G14 -> 1392.72 | H14: =O13 -> 157948.08 | I14: ='Parcelas Mensais'!I14 -> 5825.37 | J14: ='Parcelas Mensais'!J14 -> 0.0095996867 | L14: =O14 -> 156555.36 | N14: =O14 -> 156555.36 | O14: =H14-IF(G14="",0,G14) -> 156555.36 | P14: ='Parcelas Mensais'!P14 -> 0 | Q14: ='Parcelas Mensais'!Q14 -> 0
B15: 5 | C15: 2021 | D15: AGO | E15: ='Parcelas Mensais'!E15 -> 44413 | F15: =H15/116 -> 1349.6152 | G15: ='Parcelas Mensais'!G15 -> 1392.72 | H15: =O14 -> 156555.36 | I15: ='Parcelas Mensais'!I15 -> 5876.05 | J15: ='Parcelas Mensais'!J15 -> 0.0086998766 | L15: =O15 -> 155162.64 | N15: =O15 -> 155162.64 | O15: =H15-IF(G15="",0,G15) -> 155162.64 | P15: ='Parcelas Mensais'!P15 -> 0 | Q15: ='Parcelas Mensais'!Q15 -> 0
B16: 6 | C16: 2021 | D16: SET | E16: ='Parcelas Mensais'!E16 -> 44449 | F16: =H16/115 -> 1349.2403 | G16: ='Parcelas Mensais'!G16 -> 1392.72 | H16: =O15 -> 155162.64 | I16: ='Parcelas Mensais'!I16 -> 5944.21 | J16: ='Parcelas Mensais'!J16 -> 0.011599629 | L16: =O16 -> 153769.92 | N16: =O16 -> 153769.92 | O16: =H16-IF(G16="",0,G16) -> 153769.92 | P16: ='Parcelas Mensais'!P16 -> 0 | Q16: ='Parcelas Mensais'!Q16 -> 0
B17: 7 | C17: 2021 | D17: OUT | E17: ='Parcelas Mensais'!E17 -> 44480 | F17: =H17/114 -> 1348.8589 | G17: ='Parcelas Mensais'!G17 -> 1392.72 | H17: =O16 -> 153769.92 | I17: ='Parcelas Mensais'!I17 -> 6018.51 | J17: ='Parcelas Mensais'!J17 -> 0.012499558 | L17: =O17 -> 152377.2 | N17: =O17 -> 152377.2 | O17: =H17-IF(G17="",0,G17) -> 152377.2 | P17: ='Parcelas Mensais'!P17 -> 0 | Q17: ='Parcelas Mensais'!Q17 -> 0
B18: 8 | C18: 2021 | D18: NOV | E18: ='Parcelas Mensais'!E18 -> 44510 | F18: =H18/113 -> 1348.4708 | G18: ='Parcelas Mensais'!G18 -> 1392.72 | H18: =O17 -> 152377.2 | I18: ='Parcelas Mensais'!I18 -> 6075.69 | J18: ='Parcelas Mensais'!J18 -> 0.0095006904 | L18: =O18 -> 150984.48 | N18: =O18 -> 150984.48 | O18: =H18-IF(G18="",0,G18) -> 150984.48 | P18: ='Parcelas Mensais'!P18 -> 0 | Q18: ='Parcelas Mensais'!Q18 -> 0
B19: 9 | C19: 2021 | D19: DEZ | E19: ='Parcelas Mensais'!E19 -> 44540 | F19: =H19/112 -> 1348.0757 | G19: ='Parcelas Mensais'!G19 -> 1392.72 | H19: =O18 -> 150984.48 | I19: ='Parcelas Mensais'!I19 -> 6120.04 | J19: ='Parcelas Mensais'!J19 -> 0.0072995824 | L19: =O19 -> 149591.76 | N19: =O19 -> 149591.76 | O19: =H19-IF(G19="",0,G19) -> 149591.76 | P19: ='Parcelas Mensais'!P19 -> 0 | Q19: ='Parcelas Mensais'!Q19 -> 0 | S19: ='Parcelas Mensais'!S19 -> 5000
B20: 10 | C20: 2022 | D20: JAN | E20: ='Parcelas Mensais'!E20 -> 44572 | F20: =H20/111 -> 1347.6735 | G20: ='Parcelas Mensais'!G20 -> 1392.72 | H20: =O19 -> 149591.76 | I20: ='Parcelas Mensais'!I20 -> 6153.09 | J20: ='Parcelas Mensais'!J20 -> 0.0054002915 | L20: =O20 -> 148199.04 | N20: =O20 -> 148199.04 | O20: =H20-IF(G20="",0,G20) -> 148199.04 | P20: ='Parcelas Mensais'!P20 -> 27.021 | Q20: ='Parcelas Mensais'!Q20 -> 0.4458465
B21: 11 | C21: 2022 | D21: FEV | E21: ='Parcelas Mensais'!E21 -> 44602 | F21: =H21/110 -> 1347.264 | G21: ='Parcelas Mensais'!G21 -> 1392.72 | H21: =O20 -> 148199.04 | I21: ='Parcelas Mensais'!I21 -> 6215.24 | J21: ='Parcelas Mensais'!J21 -> 0.010100616 | L21: =O21 -> 146806.32 | N21: =O21 -> 146806.32 | O21: =H21-IF(G21="",0,G21) -> 146806.32 | P21: ='Parcelas Mensais'!P21 -> 0 | Q21: ='Parcelas Mensais'!Q21 -> 0
B22: 12 | C22: 2022 | D22: MAR | E22: ='Parcelas Mensais'!E22 -> 44630 | F22: =H22/109 -> 1346.847 | G22: ='Parcelas Mensais'!G22 -> 1392.72 | H22: =O21 -> 146806.32 | I22: ='Parcelas Mensais'!I22 -> 6315.93 | J22: ='Parcelas Mensais'!J22 -> 0.016200501 | K22: 0.112993 | L22: 161844.34 | M22: 17302.13 | N22: =L22+M22 -> 179146.47 | O22: =H22-IF(G22="",0,G22) -> 145413.6 | P22: ='Parcelas Mensais'!P22 -> 0 | Q22: ='Parcelas Mensais'!Q22 -> 0
B23: 13 | C23: 2022 | D23: ABR | E23: ='Parcelas Mensais'!E23 -> 44662 | F23: =H23/108 -> 1658.7636 | G23: ='Parcelas Mensais'!G23 -> 1392.72 | H23: =N22 -> 179146.47 | I23: ='Parcelas Mensais'!I23 -> 6382.88 | J23: ='Parcelas Mensais'!J23 -> 0.010600181 | L23: =O23 -> 177753.75 | N23: =O23 -> 177753.75 | O23: =H23-IF(G23="",0,G23) -> 177753.75 | P23: ='Parcelas Mensais'!P23 -> 0 | Q23: ='Parcelas Mensais'!Q23 -> 0 | R23: =Reajustes!I21 -> 45000
B24: 14 | C24: 2022 | D24: MAI | E24: ='Parcelas Mensais'!E24 -> 44691 | F24: =H24/107 -> 1661.25 | G24: ='Parcelas Mensais'!G24 -> 1392.72 | H24: =O23 -> 177753.75 | I24: ='Parcelas Mensais'!I24 -> 6412.88 | J24: ='Parcelas Mensais'!J24 -> 0.0047000727 | L24: =O24 -> 176361.03 | N24: =O24 -> 176361.03 | O24: =H24-IF(G24="",0,G24) -> 176361.03 | P24: ='Parcelas Mensais'!P24 -> 0 | Q24: ='Parcelas Mensais'!Q24 -> 0
B25: 15 | C25: 2022 | D25: JUN | E25: ='Parcelas Mensais'!E25 -> 44726 | F25: =H25/106 -> 1663.7833 | G25: ='Parcelas Mensais'!G25 -> 1392.72 | H25: =O24 -> 176361.03 | I25: ='Parcelas Mensais'!I25 -> 6455.85 | J25: ='Parcelas Mensais'!J25 -> 0.0067005776 | L25: =O25 -> 174968.31 | N25: =O25 -> 174968.31 | O25: =H25-IF(G25="",0,G25) -> 174968.31 | P25: ='Parcelas Mensais'!P25 -> 33.289335 | Q25: ='Parcelas Mensais'!Q25 -> 2.1970961
B26: 16 | C26: 2022 | D26: JUL | E26: ='Parcelas Mensais'!E26 -> 44783 | F26: =H26/105 -> 1666.3649 | G26: ='Parcelas Mensais'!G26 -> 1392.72 | H26: =O25 -> 174968.31 | I26: ='Parcelas Mensais'!I26 -> 6411.95 | J26: ='Parcelas Mensais'!J26 -> -0.0068000341 | L26: =O26 -> 173575.59 | N26: =O26 -> 173575.59 | O26: =H26-IF(G26="",0,G26) -> 173575.59 | P26: ='Parcelas Mensais'!P26 -> 33.289335 | Q26: ='Parcelas Mensais'!Q26 -> 16.478221
B27: 17 | C27: 2022 | D27: AGO | E27: ='Parcelas Mensais'!E27 -> 44844 | F27: =H27/104 -> 1668.9961 | G27: ='Parcelas Mensais'!G27 -> 1392.72 | H27: =O26 -> 173575.59 | I27: ='Parcelas Mensais'!I27 -> 6388.87 | J27: ='Parcelas Mensais'!J27 -> -0.003599529 | L27: =O27 -> 172182.87 | N27: =O27 -> 172182.87 | O27: =H27-IF(G27="",0,G27) -> 172182.87 | P27: ='Parcelas Mensais'!P27 -> 33.289335 | Q27: ='Parcelas Mensais'!Q27 -> 33.505716
B28: 18 | C28: 2022 | D28: SET | E28: ='Parcelas Mensais'!E28 -> 44876 | F28: =H28/103 -> 1671.6783 | G28: ='Parcelas Mensais'!G28 -> 1392.72 | H28: =O27 -> 172182.87 | I28: ='Parcelas Mensais'!I28 -> 6370.34 | J28: ='Parcelas Mensais'!J28 -> -0.0029003564 | L28: =O28 -> 170790.15 | N28: =O28 -> 170790.15 | O28: =H28-IF(G28="",0,G28) -> 170790.15 | P28: ='Parcelas Mensais'!P28 -> 33.289335 | Q28: ='Parcelas Mensais'!Q28 -> 32.956442
B29: 19 | C29: 2022 | D29: OUT | E29: ='Parcelas Mensais'!E29 -> 44908 | F29: =H29/102 -> 1674.4132 | G29: ='Parcelas Mensais'!G29 -> 1351.05 | H29: =O28 -> 170790.15 | I29: ='Parcelas Mensais'!I29 -> 6407.93 | J29: ='Parcelas Mensais'!J29 -> 0.0059007839 | L29: =O29 -> 169439.1 | N29: =O29 -> 169439.1 | O29: =H29-IF(G29="",0,G29) -> 169439.1 | P29: ='Parcelas Mensais'!P29 -> 33.289335 | Q29: ='Parcelas Mensais'!Q29 -> 35.153538 | S29: ='Parcelas Mensais'!S29 -> 5000
B30: 20 | C30: 2022 | D30: NOV | E30: ='Parcelas Mensais'!E30 -> 44937 | F30: =H30/101 -> 1677.6149 | G30: ='Parcelas Mensais'!G30 -> 1392.72 | H30: =O29 -> 169439.1 | I30: ='Parcelas Mensais'!I30 -> 6434.2 | J30: ='Parcelas Mensais'!J30 -> 0.0040996078 | L30: =O30 -> 168046.38 | N30: =O30 -> 168046.38 | O30: =H30-IF(G30="",0,G30) -> 168046.38 | P30: ='Parcelas Mensais'!P30 -> 33.289335 | Q30: ='Parcelas Mensais'!Q30 -> 34.05499
B31: 21 | C31: 2022 | D31: DEZ | E31: ='Parcelas Mensais'!E31 -> 44968 | F31: =H31/100 -> 1680.4638 | G31: ='Parcelas Mensais'!G31 -> 1500 | H31: =O30 -> 168046.38 | I31: ='Parcelas Mensais'!I31 -> 6474.09 | J31: ='Parcelas Mensais'!J31 -> 0.0061996829 | L31: =O31 -> 166546.38 | N31: =O31 -> 166546.38 | O31: =H31-IF(G31="",0,G31) -> 166546.38 | P31: ='Parcelas Mensais'!P31 -> 33.289335 | Q31: ='Parcelas Mensais'!Q31 -> 33.505716
B32: 22 | C32: 2023 | D32: JAN | E32: ='Parcelas Mensais'!E32 -> 44998 | F32: =H32/99 -> 1682.2867 | G32: ='Parcelas Mensais'!G32 -> 2000 | H32: =O31 -> 166546.38 | I32: ='Parcelas Mensais'!I32 -> 6508.4 | J32: ='Parcelas Mensais'!J32 -> 0.0052995865 | L32: =O32 -> 164546.38 | N32: =O32 -> 164546.38 | O32: =H32-IF(G32="",0,G32) -> 164546.38 | P32: ='Parcelas Mensais'!P32 -> 33.289335 | Q32: ='Parcelas Mensais'!Q32 -> 34.05499
B33: 23 | C33: 2023 | D33: FEV | E33: ='Parcelas Mensais'!E33 -> 45028 | F33: =H33/98 -> 1679.0447 | G33: ='Parcelas Mensais'!G33 -> 1500 | H33: =O32 -> 164546.38 | I33: ='Parcelas Mensais'!I33 -> 6563.07 | J33: ='Parcelas Mensais'!J33 -> 0.008399914 | L33: =O33 -> 163046.38 | N33: =O33 -> 163046.38 | O33: =H33-IF(G33="",0,G33) -> 163046.38 | P33: ='Parcelas Mensais'!P33 -> 33.289335 | Q33: ='Parcelas Mensais'!Q33 -> 33.505716
B34: 24 | C34: 2023 | D34: MAR | E34: ='Parcelas Mensais'!E34 -> 45056 | F34: =H34/97 -> 1680.8905 | G34: ='Parcelas Mensais'!G34 -> 1500 | H34: =O33 -> 163046.38 | I34: ='Parcelas Mensais'!I34 -> 6609.67 | J34: ='Parcelas Mensais'!J34 -> 0.0071003357 | K34: 0.046507 | L34: 169059.41 | M34: 18073.46 | N34: =L34+M34 -> 187132.87 | O34: =H34-IF(G34="",0,G34) -> 161546.38 | P34: ='Parcelas Mensais'!P34 -> 33.289335 | Q34: ='Parcelas Mensais'!Q34 -> 33.505716
B35: 25 | C35: 2023 | D35: ABR | E35: ='Parcelas Mensais'!E35 -> 45085 | F35: =H35/96 -> 1949.3007 | G35: ='Parcelas Mensais'!G35 -> 1500 | H35: =N34 -> 187132.87 | I35: ='Parcelas Mensais'!I35 -> 6649.99 | J35: ='Parcelas Mensais'!J35 -> 0.0061001533 | L35: =O35 -> 185632.87 | N35: =O35 -> 185632.87 | O35: =H35-IF(G35="",0,G35) -> 185632.87 | P35: ='Parcelas Mensais'!P35 -> 38.561899 | Q35: ='Parcelas Mensais'!Q35 -> 37.540009 | R35: =Reajustes!I22 -> 46335.44
B36: 26 | C36: 2023 | D36: MAI | E36: ='Parcelas Mensais'!E36 -> 45118 | F36: =H36/95 -> 1954.0302 | G36: ='Parcelas Mensais'!G36 -> 1500 | H36: =O35 -> 185632.87 | I36: ='Parcelas Mensais'!I36 -> 6665.28 | J36: ='Parcelas Mensais'!J36 -> 0.0022992516 | L36: =O36 -> 184132.87 | N36: =O36 -> 184132.87 | O36: =H36-IF(G36="",0,G36) -> 184132.87 | P36: ='Parcelas Mensais'!P36 -> 38.561899 | Q36: ='Parcelas Mensais'!Q36 -> 39.448823
B37: 27 | C37: 2023 | D37: JUN | E37: ='Parcelas Mensais'!E37 -> 45148 | F37: =H37/94 -> 1958.8603 | G37: ='Parcelas Mensais'!G37 -> 1500 | H37: =O36 -> 184132.87 | I37: ='Parcelas Mensais'!I37 -> 6659.95 | J37: ='Parcelas Mensais'!J37 -> -0.00079966633 | L37: =O37 -> 182632.87 | N37: =O37 -> 182632.87 | O37: =H37-IF(G37="",0,G37) -> 182632.87 | P37: ='Parcelas Mensais'!P37 -> 38.561899 | Q37: ='Parcelas Mensais'!Q37 -> 37.540009
B38: 28 | C38: 2023 | D38: JUL | E38: ='Parcelas Mensais'!E38 -> 45182 | F38: =H38/93 -> 1963.7943 | G38: ='Parcelas Mensais'!G38 -> 1500 | H38: =O37 -> 182632.87 | I38: ='Parcelas Mensais'!I38 -> 6667.94 | J38: ='Parcelas Mensais'!J38 -> 0.0011997087 | L38: =O38 -> 181132.87 | N38: =O38 -> 181132.87 | O38: =H38-IF(G38="",0,G38) -> 181132.87 | P38: ='Parcelas Mensais'!P38 -> 38.561899 | Q38: ='Parcelas Mensais'!Q38 -> 41.357637
B39: 29 | C39: 2023 | D39: AGO | E39: ='Parcelas Mensais'!E39 -> 0 | F39: =H39/92 -> 1968.8355 | G39: ='Parcelas Mensais'!G39 -> 0 | H39: =O38 -> 181132.87 | I39: ='Parcelas Mensais'!I39 -> 6683.28 | J39: ='Parcelas Mensais'!J39 -> 0.0023005606 | L39: =O39 -> 181132.87 | N39: =O39 -> 181132.87 | O39: =H39-IF(G39="",0,G39) -> 181132.87 | P39: ='Parcelas Mensais'!P39 -> 0 | Q39: ='Parcelas Mensais'!Q39 -> 0
B40: 30 | C40: 2023 | D40: SET | E40: ='Parcelas Mensais'!E40 -> 0 | F40: =H40/91 -> 1990.4711 | G40: ='Parcelas Mensais'!G40 -> 0 | H40: =O39 -> 181132.87 | I40: ='Parcelas Mensais'!I40 -> 6700.66 | J40: ='Parcelas Mensais'!J40 -> 0.0026005195 | L40: =O40 -> 181132.87 | N40: =O40 -> 181132.87 | O40: =H40-IF(G40="",0,G40) -> 181132.87 | P40: ='Parcelas Mensais'!P40 -> 0 | Q40: ='Parcelas Mensais'!Q40 -> 0
B41: 31 | C41: 2023 | D41: OUT | E41: ='Parcelas Mensais'!E41 -> 0 | F41: =H41/90 -> 2012.5874 | G41: ='Parcelas Mensais'!G41 -> 0 | H41: =O40 -> 181132.87 | I41: ='Parcelas Mensais'!I41 -> 6716.74 | J41: ='Parcelas Mensais'!J41 -> 0.0023997636 | L41: =O41 -> 181132.87 | N41: =O41 -> 181132.87 | O41: =H41-IF(G41="",0,G41) -> 181132.87 | P41: ='Parcelas Mensais'!P41 -> 0 | Q41: ='Parcelas Mensais'!Q41 -> 0
...
